Workbook
Name PeriodSynch: 'Summary by Vendor'!$C$2:$G$3
Name PeriodSynch: 'Summary by Sales Channels'!$C$2:$G$3

Sheet Polish Goals
A2: 1 | B2: Apply per item order actual invoice amount from KS
A3: 2 | B3: Apply per item order actual invoice amount from TAAS
A4: 3 | B4: Apply per item order actual invoice amout from Wally's
A5: 4 | B5: Apply per actual UPS shipping cost amount per item order
A6: 5 | B6: Add monthly storage charges

Sheet Summary by Sales Channels
B2: Report | C2: Year to Date | D2: Last Month | E2: Month to Date | F2: This Week | G2: Last Week | I2: Performance/ Analysis
C3: 2025 | D3: November | E3: December | F3: 45999 | G3: =F3-7 -> 45992 | I3: Last Year | J3: =D3 -> November | K3: =E3 -> December | L3: =I3 -> Last Year | M3: =J3 -> November | N3: =K3 -> December
B4: Sales | I4: Sales | L4: Net Margin
B5: All Channels/ Vendor | C5: =SUM(C6:C10) -> 1484781.9 | D5: =SUM(D6:D10) -> 105629.45 | E5: =SUM(E6:E10) -> 56468.77 | F5: =SUM(F6:F10) -> 19198.51 | G5: =SUM(G6:G10) -> 22237.94 | I5: All Channels/ Vendor
B6: AL's Supply | C6: ='Als Supply'!C36 -> 1068091.1 | D6: ='Als Supply'!D36 -> 86933.69 | E6: ='Als Supply'!E36 -> 50289.99 | F6: ='Als Supply'!F36 -> 16071.94 | G6: ='Als Supply'!G36 -> 18873.88
B7: Fuel Rider | C7: ='Fuel Rider'!C40 -> 248984.2 | D7: ='Fuel Rider'!D40 -> 4660.5 | E7: ='Fuel Rider'!E40 -> 3487.34 | F7: ='Fuel Rider'!F40 -> 956.46 | G7: ='Fuel Rider'!G40 -> 717.2 | I7: Growth Sales | L7: Growth Net Margin
B8: SOT | C8: =SOT!C40 -> 21943.89 | D8: =SOT!D40 -> 1061.29 | E8: =SOT!E40 -> 835.1 | F8: =SOT!F40 -> 313.77 | G8: =SOT!G40 -> 678.82 | I8: All Channels/ Vendor
B9: Covershield | C9: =Covershield!C26 -> 112488.71 | D9: =Covershield!D26 -> 8729.17 | E9: =Covershield!E26 -> 1856.34 | F9: =Covershield!F26 -> 1856.34 | G9: =Covershield!G26 -> 1968.04
B10: Walmart | C10: =Walmart!C28 -> 33274 | D10: =Walmart!D28 -> 4244.8 | E10: =Walmart!E28 -> 0 | F10: =Walmart!F28 -> 0 | G10: =Walmart!G28 -> 0
I11: By (%)
B12: Net Margin By Sales Channels | C12: =$C3 -> 2025 | D12: =$D3 -> November | E12: =$E3 -> December | F12: This Week | G12: Last Week | I12: Net Margin By Sales Channels | J12: =$C3 -> 2025 | K12: =$D3 -> November | L12: =$E3 -> December | M12: This Week | N12: Last Week
B13: NMDCP | C13: =C14*20% -> 78605.79 | D13: =D14*20% -> 5107.0872 | E13: =E14*20% -> 2645.9293 | F13: =F14*20% -> 694.38734 | G13: =G14*20% -> 648.08976
B14: All Sales Channels | C14: =SUM(C15:C19) -> 393028.95 | D14: =SUM(D15:D19) -> 25535.436 | E14: =SUM(E15:E19) -> 13229.647 | F14: =SUM(F15:F19) -> 3471.9367 | G14: =SUM(G15:G19) -> 3240.4488 | I14: All Sales Channels | J14: =iferror(C14/C5,0%) -> 0.26470484 | K14: =iferror(D14/D5,0%) -> 0.24174542 | L14: =iferror(E14/E5,0%) -> 0.23428254 | M14: =iferror(F14/F5,0%) -> 0.18084407 | N14: =iferror(G14/G5,0%) -> 0.14571713
B15: A's Supply | C15: ='Als Supply'!C5 -> 286608.72 | D15: ='Als Supply'!D5 -> 23492.79 | E15: ='Als Supply'!E5 -> 12933.76 | F15: ='Als Supply'!F5 -> 3827.08 | G15: ='Als Supply'!G5 -> 4254.41 | I15: A's Supply | J15: =iferror(C15/C6,0%) -> 0.26833735 | K15: =iferror(D15/D6,0%) -> 0.27023804 | L15: =iferror(E15/E6,0%) -> 0.25718359 | M15: =iferror(F15/F6,0%) -> 0.23812184 | N15: =iferror(G15/G6,0%) -> 0.22541258
B16: Fuel Rider | C16: ='Fuel Rider'!C5 -> 74647.05 | D16: ='Fuel Rider'!D5 -> -555.26 | E16: ='Fuel Rider'!E5 -> -102.95 | F16: ='Fuel Rider'!F5 -> -873.72 | G16: ='Fuel Rider'!G5 -> -1401.07 | I16: Fuel Rider | J16: =iferror(C16/C7,0%) -> 0.29980637 | K16: =iferror(D16/D7,0%) -> -0.11914172 | L16: =iferror(E16/E7,0%) -> -0.029521068 | M16: =iferror(F16/F7,0%) -> -0.91349351 | N16: =iferror(G16/G7,0%) -> -1.9535276
B17: SOT | C17: =SOT!C5 -> 308.9 | D17: =SOT!D5 -> -204.26 | E17: =SOT!E5 -> -211.56 | F17: =SOT!F5 -> -91.82 | G17: =SOT!G5 -> -26.67 | I17: SOT | J17: =iferror(C17/C8,0%) -> 0.014076811 | K17: =iferror(D17/D8,0%) -> -0.19246389 | L17: =iferror(E17/E8,0%) -> -0.25333493 | M17: =iferror(F17/F8,0%) -> -0.29263473 | N17: =iferror(G17/G8,0%) -> -0.039288766
B18: Covershield | C18: =Covershield!C5 -> 23474.519 | D18: =Covershield!D5 -> 1622.1659 | E18: =Covershield!E5 -> 610.39672 | F18: =Covershield!F5 -> 610.39672 | G18: =Covershield!G5 -> 413.77882 | I18: Covershield | J18: =iferror(C18/C9,0%) -> 0.20868334 | K18: =iferror(D18/D9,0%) -> 0.18583278 | L18: =iferror(E18/E9,0%) -> 0.32881731 | M18: =iferror(F18/F9,0%) -> 0.32881731 | N18: =iferror(G18/G9,0%) -> 0.21024919
B19: Walmart | C19: =Walmart!C5 -> 7989.76 | D19: =Walmart!D5 -> 1180 | E19: =Walmart!E5 -> 0 | F19: =Walmart!F5 -> 0 | G19: =Walmart!G5 -> 0 | I19: Walmart | J19: =iferror(C19/C10,0%) -> 0.24012021 | K19: =iferror(D19/D10,0%) -> 0.27798718 | L19: =iferror(E19/E10,0%) -> 0 | M19: =iferror(F19/F10,0%) -> 0 | N19: =iferror(G19/G10,0%) -> 0
B21: Returns | C21: =C12 -> 2025 | D21: =D12 -> November | E21: =E12 -> December | F21: =F12 -> This Week | G21: =G12 -> Last Week
B22: All Channels/ Vendor | C22: =SUM(C23:C27) -> -92111.34 | D22: =SUM(D23:D27) -> -5445.45 | E22: =SUM(E23:E27) -> -3156.75 | F22: =SUM(F23:F27) -> -1434.05 | G22: =SUM(G23:G27) -> -1279.64
B23: AL's Supply | C23: ='Als Supply'!C14 -> -60757.31 | D23: ='Als Supply'!D14 -> -3702.38 | E23: ='Als Supply'!E14 -> -2665.31 | F23: ='Als Supply'!F14 -> -1118.94 | G23: ='Als Supply'!G14 -> -1030.49
B24: Fuel Rider | C24: ='Fuel Rider'!C16 -> -14465.01 | D24: ='Fuel Rider'!D16 -> -258.23 | E24: ='Fuel Rider'!E16 -> -95.52 | F24: ='Fuel Rider'!F16 -> -20.83 | G24: ='Fuel Rider'!G16 -> -42.15
B25: SOT | C25: =SOT!C16 -> -2922.09 | D25: =SOT!D16 -> -71.64 | E25: =SOT!E16 -> -127.65 | F25: =SOT!F16 -> -26.01 | G25: =SOT!G16 -> 0
B26: Covershield | C26: =Covershield!C12 -> -10237.49 | D26: =Covershield!D12 -> -1035.66 | E26: =Covershield!E12 -> -268.27 | F26: =Covershield!F12 -> -268.27 | G26: =Covershield!G12 -> -207
B27: Walmart | C27: =Walmart!C12 -> -3729.44 | D27: =Walmart!D12 -> -377.54 | E27: =Walmart!E12 -> 0 | F27: =Walmart!F12 -> 0 | G27: =Walmart!G12 -> 0

Sheet Summary by Vendor
B2: Sales Report | C2: Year to Date | D2: Last Month | E2: Month to Date | F2: This Week | G2: Last Week
C3: 2025 | D3: October | E3: November | F3: 45982 | G3: =F3-7 -> 45975
B4: Keystone | C4: ='Als Supply'!C37+'Fuel Rider'!C41+SOT!C41+Covershield!C27+Walmart!C29 -> 1369406 | D4: ='Als Supply'!D37+'Fuel Rider'!D41+SOT!E41+Covershield!D27+Walmart!D29 -> 99556.9 | E4: ='Als Supply'!E37+'Fuel Rider'!E41+SOT!E41+Covershield!E27+Walmart!E29 -> 52419.1 | F4: ='Als Supply'!F37+'Fuel Rider'!F41+SOT!F41+Covershield!F27+Walmart!F29 -> 17704.49 | G4: ='Als Supply'!G37+'Fuel Rider'!G41+SOT!G41+Covershield!G27+Walmart!G29 -> 21089.05
B5: eBay | C5: ='Als Supply'!C38+'Fuel Rider'!C42+SOT!C42 -> 86453.16 | D5: ='Als Supply'!D38+'Fuel Rider'!D42+SOT!D42 -> 4840.08 | E5: ='Als Supply'!E38+'Fuel Rider'!E42+SOT!E42 -> 2683.81 | F5: ='Als Supply'!F38+'Fuel Rider'!F42+SOT!F42 -> 1111.76 | G5: ='Als Supply'!G38+'Fuel Rider'!G42+SOT!G42 -> 939.95
B6: TAAS | C6: ='Als Supply'!C40+'Fuel Rider'!C43+SOT!C43+Covershield!C28 -> 16868.32 | D6: ='Als Supply'!D40+'Fuel Rider'!D43+SOT!D43+Covershield!D28 -> 373.78 | E6: ='Als Supply'!E40+'Fuel Rider'!E43+SOT!E43+Covershield!E28 -> 363.08 | F6: ='Als Supply'!F40+'Fuel Rider'!F43+SOT!F43+Covershield!F28 -> 156.46 | G6: ='Als Supply'!G40+'Fuel Rider'!G43+SOT!G43+Covershield!G28 -> 78.23
B7: Wally's | C7: ='Fuel Rider'!C44+SOT!C44+Covershield!C29 -> 7295.16 | D7: ='Fuel Rider'!D44+SOT!D44+Covershield!D29 -> 219.74 | E7: ='Fuel Rider'!E44+SOT!E44+Covershield!E29 -> 333.14 | F7: ='Fuel Rider'!F44+SOT!F44+Covershield!F29 -> 69.44 | G7: ='Fuel Rider'!G44+SOT!G44+Covershield!G29 -> 87.9
B8: NDMCP-FBA | C8: ='Als Supply'!C41 -> 2483.89 | D8: ='Als Supply'!D41 -> 217.92 | E8: ='Als Supply'!E41 -> 329.62 | F8: ='Als Supply'!F41 -> 144.75 | G8: ='Als Supply'!G41 -> 34.13
B9: RR-FBA | C9: ='Als Supply'!C39+'Fuel Rider'!C45+SOT!C45 -> 1377.82 | D9: ='Als Supply'!D39+'Fuel Rider'!D45+SOT!D45 -> 120.22 | E9: ='Als Supply'!E39+'Fuel Rider'!E45+SOT!E45 -> 340.02 | F9: ='Als Supply'!F39+'Fuel Rider'!F45+SOT!F45 -> 11.61 | G9: ='Als Supply'!G39+'Fuel Rider'!G45+SOT!G45 -> 8.68
B11: Net Margin
B12: Keystone | C12: ='Als Supply'!C8+'Fuel Rider'!C8+SOT!C8+Covershield!C8+Walmart!C8 -> 471545.1 | D12: ='Als Supply'!D8+'Fuel Rider'!D8+SOT!D8+Covershield!D8+Walmart!D8 -> 32535.546 | E12: ='Als Supply'!E8+'Fuel Rider'!E8+SOT!E8+Covershield!E8+Walmart!E8 -> 17488.507 | F12: ='Als Supply'!F8+'Fuel Rider'!F8+SOT!F8+Covershield!F8+Walmart!F8 -> 6087.8967 | G12: ='Als Supply'!G8+'Fuel Rider'!G8+SOT!G8+Covershield!G8+Walmart!G8 -> 6318.3088
B13: eBay | C13: ='Als Supply'!C9+'Fuel Rider'!C9+SOT!C9+Walmart!C9 -> 38125.56 | D13: ='Als Supply'!D9+'Fuel Rider'!D9+SOT!D9+Walmart!D9 -> 2166.32 | E13: ='Als Supply'!E9+'Fuel Rider'!E9+SOT!E9+Walmart!E9 -> 1284.83 | F13: ='Als Supply'!F9+'Fuel Rider'!F9+SOT!F9+Walmart!F9 -> 542.54 | G13: ='Als Supply'!G9+'Fuel Rider'!G9+SOT!G9+Walmart!G9 -> 352.19
B14: TAAS | C14: ='Als Supply'!C11+'Fuel Rider'!C10+SOT!C10+Covershield!C9 -> 6206.31 | D14: ='Als Supply'!D11+'Fuel Rider'!D10+SOT!D10+Covershield!D9 -> 0 | E14: ='Als Supply'!E11+'Fuel Rider'!E10+SOT!E10+Covershield!E9 -> 0 | F14: ='Als Supply'!F11+'Fuel Rider'!F10+SOT!F10+Covershield!F9 -> 0 | G14: ='Als Supply'!G11+'Fuel Rider'!G10+SOT!G10+Covershield!G9 -> 0
B15: TAS- Returns | C15: ='Fuel Rider'!C13+SOT!C13 -> 596.21 | D15: ='Fuel Rider'!D13+SOT!D13 -> 0 | E15: ='Fuel Rider'!E13+SOT!E13 -> 0 | F15: ='Fuel Rider'!F13+SOT!F13 -> 0 | G15: ='Fuel Rider'!G13+SOT!G13 -> 0
B16: Wally's | C16: ='Fuel Rider'!C11+SOT!C11+Covershield!C10 -> 5100.8932 | D16: ='Fuel Rider'!D11+SOT!D11+Covershield!D10 -> 177.74 | E16: ='Fuel Rider'!E11+SOT!E11+Covershield!E10 -> 273.14 | F16: ='Fuel Rider'!F11+SOT!F11+Covershield!F10 -> 57.44 | G16: ='Fuel Rider'!G11+SOT!G11+Covershield!G10 -> 69.9
B17: NDMCP-FBA | C17: ='Als Supply'!C12 -> 1015.4 | D17: ='Als Supply'!D12 -> 23.64 | E17: ='Als Supply'!E12 -> 49.95 | F17: ='Als Supply'!F12 -> 7.15 | G17: ='Als Supply'!G12 -> 0
B18: RR-FBA | C18: ='Als Supply'!C10+'Fuel Rider'!C12+SOT!C12 -> 930.83 | D18: ='Als Supply'!D10+'Fuel Rider'!D12+SOT!D12 -> 40.52 | E18: ='Als Supply'!E10+'Fuel Rider'!E12+SOT!E12 -> 171.41 | F18: ='Als Supply'!F10+'Fuel Rider'!F12+SOT!F12 -> 1.23 | G18: ='Als Supply'!G10+'Fuel Rider'!G12+SOT!G12 -> 0
I19: Actual Invoices
B20: Purchase Reconciliations | C20: =C3 -> 2025 | D20: =D3 -> October | E20: =E3 -> November | F20: =F2 -> This Week | G20: =G2 -> Last Week | J20: =C20 -> 2025 | K20: =D20 -> October | L20: =E20 -> November | M20: =F20 -> This Week | N20: =G20 -> Last Week
B21: Keystone | C21: ='Als Supply'!C31+'Fuel Rider'!C35+SOT!C35+Covershield!C21+Walmart!C22 -> 869553 | D21: ='Als Supply'!D31+'Fuel Rider'!D35+SOT!D35+Covershield!D21+Walmart!D22 -> 62550.56 | E21: ='Als Supply'!E31+'Fuel Rider'!E35+SOT!E35+Covershield!E21+Walmart!E22 -> 32865.92 | F21: ='Als Supply'!F31+'Fuel Rider'!F35+SOT!F35+Covershield!F21+Walmart!F22 -> 10851.38 | G21: ='Als Supply'!G31+'Fuel Rider'!G35+SOT!G35+Covershield!G21+Walmart!G22 -> 12981.46 | K21: -102033.48
B22: eBay | C22: ='Als Supply'!C32+'Fuel Rider'!C36+SOT!C36 -> 46159.34 | D22: ='Als Supply'!D32+'Fuel Rider'!D36+SOT!D36 -> 2225.13 | E22: ='Als Supply'!E32+'Fuel Rider'!E36+SOT!E36 -> 1249.95 | F22: ='Als Supply'!F32+'Fuel Rider'!F36+SOT!F36 -> 0 | G22: ='Als Supply'!G32+'Fuel Rider'!G36+SOT!G36 -> 0
B23: TAAS | C23: ='Als Supply'!C40+'Fuel Rider'!C43+'Fuel Rider'!C46+SOT!C43+SOT!C45 -> 17678.27 | D23: ='Als Supply'!D40+'Fuel Rider'!D43+'Fuel Rider'!D46+SOT!D43+SOT!D46 -> 373.78 | E23: ='Als Supply'!E40+'Fuel Rider'!E43+'Fuel Rider'!E46+SOT!E43+SOT!E46+Covershield!F22 -> 363.08 | F23: ='Als Supply'!F40+'Fuel Rider'!F43+'Fuel Rider'!F46+SOT!F43+SOT!F46 -> 156.46 | G23: ='Als Supply'!G40+'Fuel Rider'!G43+'Fuel Rider'!G46+SOT!G43+SOT!G46+Covershield!G22 -> 78.23

Sheet Net Margin Summary and Actual
A1: Year | B1: Month -> | C1: YTD | D1: AVE MO | E1: January | F1: February | G1: March | H1: April | I1: May | J1: June | K1: July | L1: August | M1: September | N1: October | O1: November | P1: December
A2: 2023 | B2: Total Net | C2: =SUM(E2:P2) -> 454505.01 | D2: =AVERAGE(E2:P2) -> 37875.418 | E2: 5894.55 | F2: 12178.45 | G2: 16096.24 | H2: 19744.5 | I2: 49416.57 | J2: 34363.85 | K2: 59455.81 | L2: 83334.73 | M2: 72073.85 | N2: 37482.92 | O2: 26202.21 | P2: 38261.33
A3: 2024 | B3: Total Disbursement | C3: =SUM(E3:P3) -> 2338353.1 | D3: =AVERAGE(E3:P3) -> 194862.76 | E3: 161702.98 | F3: 212072.77 | G3: 269701.4 | H3: 242356.69 | I3: 225137.47 | J3: 199686.88 | K3: 171930.53 | L3: 199386.99 | M3: 159803.11 | N3: 171207.23 | O3: 171207.23 | P3: 154159.78
B4: Total Expenses | C4: =SUM(E4:P4) -> -1850274.9 | E4: -126158.49 | F4: -183929.07 | G4: -239393.35 | H4: -181980.05 | I4: -208540.04 | J4: -144181.89 | K4: -124392.42 | L4: -165856.07 | M4: -101348.98 | N4: -120621.85 | O4: -118039.32 | P4: -135833.4
B5: Total Net | C5: =SUM(E5:P5) -> 493789.19 | D5: =AVERAGE(E5:P5) -> 41149.099 | E5: 35544.49 | F5: 31847.12 | G5: 32026.72 | H5: 60665.61 | I5: 16597.43 | J5: 55504.99 | K5: 47538.11 | L5: 33530.92 | M5: 58454.13 | N5: 50585.38 | O5: 53167.91 | P5: 18326.38
B6: 0.2 | C6: =SUM(E6:P6) -> 98757.84 | D6: =AVERAGE(E6:P6) -> 8229.82 | E6: 7108.9 | F6: 6369.42 | G6: 6405.34 | H6: 12133.12 | I6: 3319.49 | J6: 11101 | K6: 9507.62 | L6: 6706.18 | M6: 11690.83 | N6: 10117.08 | O6: 10633.58 | P6: 3665.28
A7: 2025 | B7: Total Disbursement | C7: =SUM(E7:P7) -> 588365.53 | D7: =AVERAGE(E7:P7) -> 117673.11 | E7: 95578.89 | F7: 89875.62 | G7: 132309.72 | H7: 131539.43 | I7: 139061.87
B8: Total Expenses | C8: =SUM(E8:P8) -> -504791.29 | E8: -82812.64 | F8: -80380.09 | G8: -121198.95 | H8: -106768.27 | I8: -113631.34
B9: Total Net | C9: =SUM(E9:P9) -> 83574.24 | D9: =AVERAGE(E9:P9) -> 16714.848 | E9: 12766.25 | F9: 9495.53 | G9: 11110.77 | H9: 24771.16 | I9: 25430.53
B10: 0.2 | C10: =SUM(E10:P10) -> 16714.846 | D10: =AVERAGE(E10:P10) -> 3342.9692 | E10: 2553.25 | F10: 1899.11 | G10: 2222.15 | H10: 4954.23 | I10: =I9*0.2 -> 5086.106

Sheet Als  Supply
A1: =IFERROR(__xludf.DUMMYFUNCTION("importrange(""https://docs.google.com/spreadsheets/d/1uDBYp-3aTlfiMQ7ZzS-0EHO4IrHZRSRphZz4VDj1_ws/edit?gid=907455009#gid=907455009"",""AlsSupply"")"),"") | B1: =IFERROR(__xludf.DUMMYFUNCTION("""COMPUTED_VALUE"""),"Al's Supply Profitability Report") -> Al's Supply Profitability Report
B2: =IFERROR(__xludf.DUMMYFUNCTION("""COMPUTED_VALUE"""),"Net Margins") -> Net Margins | C2: =IFERROR(__xludf.DUMMYFUNCTION("""COMPUTED_VALUE"""),"Year to Date") -> Year to Date | D2: =IFERROR(__xludf.DUMMYFUNCTION("""COMPUTED_VALUE"""),"Last Month") -> Last Month | E2: =IFERROR(__xludf.DUMMYFUNCTION("""COMPUTED_VALUE"""),"Month to Date") -> Month to Date | F2: =IFERROR(__xludf.DUMMYFUNCTION("""COMPUTED_VALUE"""),"This Week") -> This Week | G2: =IFERROR(__xludf.DUMMYFUNCTION("""COMPUTED_VALUE"""),"Last Week") -> Last Week
C3: =IFERROR(__xludf.DUMMYFUNCTION("""COMPUTED_VALUE"""),2025.0) -> 2025 | D3: =IFERROR(__xludf.DUMMYFUNCTION("""COMPUTED_VALUE"""),"November") -> November | E3: =IFERROR(__xludf.DUMMYFUNCTION("""COMPUTED_VALUE"""),"December") -> December | F3: =IFERROR(__xludf.DUMMYFUNCTION("""COMPUTED_VALUE"""),45999.0) -> 45999 | G3: =IFERROR(__xludf.DUMMYFUNCTION("""COMPUTED_VALUE"""),45992.0) -> 45992
B4: =IFERROR(__xludf.DUMMYFUNCTION("""COMPUTED_VALUE"""),"20% Projection") -> 20% Projection | C4: =IFERROR(__xludf.DUMMYFUNCTION("""COMPUTED_VALUE"""),57321.744000001374) -> 57321.744 | D4: =IFERROR(__xludf.DUMMYFUNCTION("""COMPUTED_VALUE"""),4698.558000000017) -> 4698.558 | E4: =IFERROR(__xludf.DUMMYFUNCTION("""COMPUTED_VALUE"""),2586.7520000000086) -> 2586.752 | F4: =IFERROR(__xludf.DUMMYFUNCTION("""COMPUTED_VALUE"""),765.4160000000006) -> 765.416 | G4: =IFERROR(__xludf.DUMMYFUNCTION("""COMPUTED_VALUE"""),850.8820000000002) -> 850.882 | H4: =IFERROR(__xludf.DUMMYFUNCTION("""COMPUTED_VALUE"""),"x") -> x
B5: =IFERROR(__xludf.DUMMYFUNCTION("""COMPUTED_VALUE"""),"Net Profit Al's Supply") -> Net Profit Al's Supply | C5: =IFERROR(__xludf.DUMMYFUNCTION("""COMPUTED_VALUE"""),286608.72000000684) -> 286608.72 | D5: =IFERROR(__xludf.DUMMYFUNCTION("""COMPUTED_VALUE"""),23492.790000000085) -> 23492.79 | E5: =IFERROR(__xludf.DUMMYFUNCTION("""COMPUTED_VALUE"""),12933.760000000042) -> 12933.76 | F5: =IFERROR(__xludf.DUMMYFUNCTION("""COMPUTED_VALUE"""),3827.0800000000027) -> 3827.08 | G5: =IFERROR(__xludf.DUMMYFUNCTION("""COMPUTED_VALUE"""),4254.410000000001) -> 4254.41
B6: =IFERROR(__xludf.DUMMYFUNCTION("""COMPUTED_VALUE"""),"Item Profit Vs. Returned Items") -> Item Profit Vs. Returned Items | C6: =IFERROR(__xludf.DUMMYFUNCTION("""COMPUTED_VALUE"""),310837.66000000667) -> 310837.66 | D6: =IFERROR(__xludf.DUMMYFUNCTION("""COMPUTED_VALUE"""),25260.190000000082) -> 25260.19 | E6: =IFERROR(__xludf.DUMMYFUNCTION("""COMPUTED_VALUE"""),14043.180000000042) -> 14043.18 | F6: =IFERROR(__xludf.DUMMYFUNCTION("""COMPUTED_VALUE"""),4303.650000000002) -> 4303.65 | G6: =IFERROR(__xludf.DUMMYFUNCTION("""COMPUTED_VALUE"""),4778.460000000001) -> 4778.46
B7: =IFERROR(__xludf.DUMMYFUNCTION("""COMPUTED_VALUE"""),"Al's Supply Item Sales Profit") -> Al's Supply Item Sales Profit | C7: =IFERROR(__xludf.DUMMYFUNCTION("""COMPUTED_VALUE"""),371594.9700000066) -> 371594.97 | D7: =IFERROR(__xludf.DUMMYFUNCTION("""COMPUTED_VALUE"""),28962.570000000083) -> 28962.57 | E7: =IFERROR(__xludf.DUMMYFUNCTION("""COMPUTED_VALUE"""),16708.49000000004) -> 16708.49 | F7: =IFERROR(__xludf.DUMMYFUNCTION("""COMPUTED_VALUE"""),5422.590000000002) -> 5422.59 | G7: =IFERROR(__xludf.DUMMYFUNCTION("""COMPUTED_VALUE"""),5808.950000000001) -> 5808.95
B8: =IFERROR(__xludf.DUMMYFUNCTION("""COMPUTED_VALUE"""),"Keystone") -> Keystone | C8: =IFERROR(__xludf.DUMMYFUNCTION("""COMPUTED_VALUE"""),328029.41000000655) -> 328029.41 | D8: =IFERROR(__xludf.DUMMYFUNCTION("""COMPUTED_VALUE"""),26754.860000000084) -> 26754.86 | E8: =IFERROR(__xludf.DUMMYFUNCTION("""COMPUTED_VALUE"""),15202.300000000041) -> 15202.3 | F8: =IFERROR(__xludf.DUMMYFUNCTION("""COMPUTED_VALUE"""),4871.670000000003) -> 4871.67 | G8: =IFERROR(__xludf.DUMMYFUNCTION("""COMPUTED_VALUE"""),5479.530000000001) -> 5479.53
B9: =IFERROR(__xludf.DUMMYFUNCTION("""COMPUTED_VALUE"""),"eBay") -> eBay | C9: =IFERROR(__xludf.DUMMYFUNCTION("""COMPUTED_VALUE"""),37705.31000000007) -> 37705.31 | D9: =IFERROR(__xludf.DUMMYFUNCTION("""COMPUTED_VALUE"""),2143.55) -> 2143.55 | E9: =IFERROR(__xludf.DUMMYFUNCTION("""COMPUTED_VALUE"""),1284.83) -> 1284.83 | F9: =IFERROR(__xludf.DUMMYFUNCTION("""COMPUTED_VALUE"""),542.54) -> 542.54 | G9: =IFERROR(__xludf.DUMMYFUNCTION("""COMPUTED_VALUE"""),329.42000000000013) -> 329.42
B10: =IFERROR(__xludf.DUMMYFUNCTION("""COMPUTED_VALUE"""),"RR-FBA") -> RR-FBA | C10: =IFERROR(__xludf.DUMMYFUNCTION("""COMPUTED_VALUE"""),712.860000000001) -> 712.86 | D10: =IFERROR(__xludf.DUMMYFUNCTION("""COMPUTED_VALUE"""),40.52) -> 40.52 | E10: =IFERROR(__xludf.DUMMYFUNCTION("""COMPUTED_VALUE"""),171.40999999999997) -> 171.41 | F10: =IFERROR(__xludf.DUMMYFUNCTION("""COMPUTED_VALUE"""),1.23) -> 1.23 | G10: =IFERROR(__xludf.DUMMYFUNCTION("""COMPUTED_VALUE"""),0.0) -> 0
B11: =IFERROR(__xludf.DUMMYFUNCTION("""COMPUTED_VALUE"""),"TAAS") -> TAAS | C11: =IFERROR(__xludf.DUMMYFUNCTION("""COMPUTED_VALUE"""),4131.989999999998) -> 4131.99 | D11: =IFERROR(__xludf.DUMMYFUNCTION("""COMPUTED_VALUE"""),0.0) -> 0 | E11: =IFERROR(__xludf.DUMMYFUNCTION("""COMPUTED_VALUE"""),0.0) -> 0 | F11: =IFERROR(__xludf.DUMMYFUNCTION("""COMPUTED_VALUE"""),0.0) -> 0 | G11: =IFERROR(__xludf.DUMMYFUNCTION("""COMPUTED_VALUE"""),0.0) -> 0
B12: =IFERROR(__xludf.DUMMYFUNCTION("""COMPUTED_VALUE"""),"Nomadic-FBA") -> Nomadic-FBA | C12: =IFERROR(__xludf.DUMMYFUNCTION("""COMPUTED_VALUE"""),1015.4000000000007) -> 1015.4 | D12: =IFERROR(__xludf.DUMMYFUNCTION("""COMPUTED_VALUE"""),23.64) -> 23.64 | E12: =IFERROR(__xludf.DUMMYFUNCTION("""COMPUTED_VALUE"""),49.95000000000002) -> 49.95 | F12: =IFERROR(__xludf.DUMMYFUNCTION("""COMPUTED_VALUE"""),7.15) -> 7.15 | G12: =IFERROR(__xludf.DUMMYFUNCTION("""COMPUTED_VALUE"""),0.0) -> 0
B14: =IFERROR(__xludf.DUMMYFUNCTION("""COMPUTED_VALUE"""),"Returns") -> Returns | C14: =IFERROR(__xludf.DUMMYFUNCTION("""COMPUTED_VALUE"""),-60757.309999999954) -> -60757.31 | D14: =IFERROR(__xludf.DUMMYFUNCTION("""COMPUTED_VALUE"""),-3702.3799999999997) -> -3702.38 | E14: =IFERROR(__xludf.DUMMYFUNCTION("""COMPUTED_VALUE"""),-2665.31) -> -2665.31 | F14: =IFERROR(__xludf.DUMMYFUNCTION("""COMPUTED_VALUE"""),-1118.9399999999996) -> -1118.94 | G14: =IFERROR(__xludf.DUMMYFUNCTION("""COMPUTED_VALUE"""),-1030.49) -> -1030.49
B15: =IFERROR(__xludf.DUMMYFUNCTION("""COMPUTED_VALUE"""),"Keystone") -> Keystone | C15: =IFERROR(__xludf.DUMMYFUNCTION("""COMPUTED_VALUE"""),-54822.11999999996) -> -54822.12 | D15: =IFERROR(__xludf.DUMMYFUNCTION("""COMPUTED_VALUE"""),-3401.8999999999996) -> -3401.9 | E15: =IFERROR(__xludf.DUMMYFUNCTION("""COMPUTED_VALUE"""),-2551.37) -> -2551.37 | F15: =IFERROR(__xludf.DUMMYFUNCTION("""COMPUTED_VALUE"""),-1107.5799999999997) -> -1107.58 | G15: =IFERROR(__xludf.DUMMYFUNCTION("""COMPUTED_VALUE"""),-814.4799999999999) -> -814.48
B16: =IFERROR(__xludf.DUMMYFUNCTION("""COMPUTED_VALUE"""),"eBay") -> eBay | C16: =IFERROR(__xludf.DUMMYFUNCTION("""COMPUTED_VALUE"""),-5421.369999999995) -> -5421.37 | D16: =IFERROR(__xludf.DUMMYFUNCTION("""COMPUTED_VALUE"""),-296.53000000000003) -> -296.53 | E16: =IFERROR(__xludf.DUMMYFUNCTION("""COMPUTED_VALUE"""),-113.94000000000001) -> -113.94 | F16: =IFERROR(__xludf.DUMMYFUNCTION("""COMPUTED_VALUE"""),-11.36) -> -11.36 | G16: =IFERROR(__xludf.DUMMYFUNCTION("""COMPUTED_VALUE"""),-216.01000000000002) -> -216.01
B17: =IFERROR(__xludf.DUMMYFUNCTION("""COMPUTED_VALUE"""),"RR-FBA") -> RR-FBA | C17: =IFERROR(__xludf.DUMMYFUNCTION("""COMPUTED_VALUE"""),-3.95) -> -3.95 | D17: =IFERROR(__xludf.DUMMYFUNCTION("""COMPUTED_VALUE"""),-3.95) -> -3.95 | E17: =IFERROR(__xludf.DUMMYFUNCTION("""COMPUTED_VALUE"""),0.0) -> 0 | F17: =IFERROR(__xludf.DUMMYFUNCTION("""COMPUTED_VALUE"""),0.0) -> 0 | G17: =IFERROR(__xludf.DUMMYFUNCTION("""COMPUTED_VALUE"""),0.0) -> 0
B18: =IFERROR(__xludf.DUMMYFUNCTION("""COMPUTED_VALUE"""),"TAAS") -> TAAS | C18: =IFERROR(__xludf.DUMMYFUNCTION("""COMPUTED_VALUE"""),-503.87) -> -503.87 | D18: =IFERROR(__xludf.DUMMYFUNCTION("""COMPUTED_VALUE"""),0.0) -> 0 | E18: =IFERROR(__xludf.DUMMYFUNCTION("""COMPUTED_VALUE"""),0.0) -> 0 | F18: =IFERROR(__xludf.DUMMYFUNCTION("""COMPUTED_VALUE"""),0.0) -> 0 | G18: =IFERROR(__xludf.DUMMYFUNCTION("""COMPUTED_VALUE"""),0.0) -> 0
B19: =IFERROR(__xludf.DUMMYFUNCTION("""COMPUTED_VALUE"""),"Nomadic-FBA") -> Nomadic-FBA | C19: =IFERROR(__xludf.DUMMYFUNCTION("""COMPUTED_VALUE"""),-6.0) -> -6 | D19: =IFERROR(__xludf.DUMMYFUNCTION("""COMPUTED_VALUE"""),0.0) -> 0 | E19: =IFERROR(__xludf.DUMMYFUNCTION("""COMPUTED_VALUE"""),0.0) -> 0 | F19: =IFERROR(__xludf.DUMMYFUNCTION("""COMPUTED_VALUE"""),0.0) -> 0 | G19: =IFERROR(__xludf.DUMMYFUNCTION("""COMPUTED_VALUE"""),0.0) -> 0
B21: =IFERROR(__xludf.DUMMYFUNCTION("""COMPUTED_VALUE"""),"Other Fees") -> Other Fees | C21: =IFERROR(__xludf.DUMMYFUNCTION("""COMPUTED_VALUE"""),-24228.939999999842) -> -24228.94 | D21: =IFERROR(__xludf.DUMMYFUNCTION("""COMPUTED_VALUE"""),-1767.3999999999999) -> -1767.4 | E21: =IFERROR(__xludf.DUMMYFUNCTION("""COMPUTED_VALUE"""),-1109.4199999999994) -> -1109.42 | F21: =IFERROR(__xludf.DUMMYFUNCTION("""COMPUTED_VALUE"""),-476.56999999999994) -> -476.57 | G21: =IFERROR(__xludf.DUMMYFUNCTION("""COMPUTED_VALUE"""),-524.0499999999998) -> -524.05
B22: =IFERROR(__xludf.DUMMYFUNCTION("""COMPUTED_VALUE"""),"Shipping Services") -> Shipping Services | C22: =IFERROR(__xludf.DUMMYFUNCTION("""COMPUTED_VALUE"""),-20935.039999999844) -> -20935.04 | D22: =IFERROR(__xludf.DUMMYFUNCTION("""COMPUTED_VALUE"""),-1691.3899999999999) -> -1691.39 | E22: =IFERROR(__xludf.DUMMYFUNCTION("""COMPUTED_VALUE"""),-952.3999999999996) -> -952.4 | F22: =IFERROR(__xludf.DUMMYFUNCTION("""COMPUTED_VALUE"""),-476.56999999999994) -> -476.57 | G22: =IFERROR(__xludf.DUMMYFUNCTION("""COMPUTED_VALUE"""),-524.0499999999998) -> -524.05
B23: =IFERROR(__xludf.DUMMYFUNCTION("""COMPUTED_VALUE"""),"FBA Inventory Fee") -> FBA Inventory Fee | C23: =IFERROR(__xludf.DUMMYFUNCTION("""COMPUTED_VALUE"""),-836.5699999999999) -> -836.57 | D23: =IFERROR(__xludf.DUMMYFUNCTION("""COMPUTED_VALUE"""),-39.58) -> -39.58 | E23: =IFERROR(__xludf.DUMMYFUNCTION("""COMPUTED_VALUE"""),-59.93) -> -59.93 | F23: =IFERROR(__xludf.DUMMYFUNCTION("""COMPUTED_VALUE"""),0.0) -> 0 | G23: =IFERROR(__xludf.DUMMYFUNCTION("""COMPUTED_VALUE"""),0.0) -> 0
B24: =IFERROR(__xludf.DUMMYFUNCTION("""COMPUTED_VALUE"""),"Service Fee") -> Service Fee | C24: =IFERROR(__xludf.DUMMYFUNCTION("""COMPUTED_VALUE"""),-2564.889999999999) -> -2564.89 | D24: =IFERROR(__xludf.DUMMYFUNCTION("""COMPUTED_VALUE"""),-39.99) -> -39.99 | E24: =IFERROR(__xludf.DUMMYFUNCTION("""COMPUTED_VALUE"""),-39.99) -> -39.99 | F24: =IFERROR(__xludf.DUMMYFUNCTION("""COMPUTED_VALUE"""),0.0) -> 0 | G24: =IFERROR(__xludf.DUMMYFUNCTION("""COMPUTED_VALUE"""),0.0) -> 0
B25: =IFERROR(__xludf.DUMMYFUNCTION("""COMPUTED_VALUE"""),"SAFE-T reimbursement") -> SAFE-T reimbursement | C25: =IFERROR(__xludf.DUMMYFUNCTION("""COMPUTED_VALUE"""),1079.55) -> 1079.55 | D25: =IFERROR(__xludf.DUMMYFUNCTION("""COMPUTED_VALUE"""),0.0) -> 0 | E25: =IFERROR(__xludf.DUMMYFUNCTION("""COMPUTED_VALUE"""),0.0) -> 0 | F25: =IFERROR(__xludf.DUMMYFUNCTION("""COMPUTED_VALUE"""),0.0) -> 0 | G25: =IFERROR(__xludf.DUMMYFUNCTION("""COMPUTED_VALUE"""),0.0) -> 0
B26: =IFERROR(__xludf.DUMMYFUNCTION("""COMPUTED_VALUE"""),"Liquidations Adjustments") -> Liquidations Adjustments | C26: =IFERROR(__xludf.DUMMYFUNCTION("""COMPUTED_VALUE"""),0.0) -> 0 | D26: =IFERROR(__xludf.DUMMYFUNCTION("""COMPUTED_VALUE"""),0.0) -> 0 | E26: =IFERROR(__xludf.DUMMYFUNCTION("""COMPUTED_VALUE"""),0.0) -> 0 | F26: =IFERROR(__xludf.DUMMYFUNCTION("""COMPUTED_VALUE"""),0.0) -> 0 | G26: =IFERROR(__xludf.DUMMYFUNCTION("""COMPUTED_VALUE"""),0.0) -> 0
B27: =IFERROR(__xludf.DUMMYFUNCTION("""COMPUTED_VALUE"""),"Adjustment") -> Adjustment | C27: =IFERROR(__xludf.DUMMYFUNCTION("""COMPUTED_VALUE"""),112.22) -> 112.22 | D27: =IFERROR(__xludf.DUMMYFUNCTION("""COMPUTED_VALUE"""),3.56) -> 3.56 | E27: =IFERROR(__xludf.DUMMYFUNCTION("""COMPUTED_VALUE"""),5.18) -> 5.18 | F27: =IFERROR(__xludf.DUMMYFUNCTION("""COMPUTED_VALUE"""),0.0) -> 0 | G27: =IFERROR(__xludf.DUMMYFUNCTION("""COMPUTED_VALUE"""),0.0) -> 0
B28: =IFERROR(__xludf.DUMMYFUNCTION("""COMPUTED_VALUE"""),"A-to-z Guarantee Claim") -> A-to-z Guarantee Claim | C28: =IFERROR(__xludf.DUMMYFUNCTION("""COMPUTED_VALUE"""),-1084.21) -> -1084.21 | D28: =IFERROR(__xludf.DUMMYFUNCTION("""COMPUTED_VALUE"""),0.0) -> 0 | E28: =IFERROR(__xludf.DUMMYFUNCTION("""COMPUTED_VALUE"""),-62.28) -> -62.28 | F28: =IFERROR(__xludf.DUMMYFUNCTION("""COMPUTED_VALUE"""),0.0) -> 0 | G28: =IFERROR(__xludf.DUMMYFUNCTION("""COMPUTED_VALUE"""),0.0) -> 0
B30: =IFERROR(__xludf.DUMMYFUNCTION("""COMPUTED_VALUE"""),"Purchase Reconciliations") -> Purchase Reconciliations
B31: =IFERROR(__xludf.DUMMYFUNCTION("""COMPUTED_VALUE"""),"Keystone") -> Keystone | C31: =IFERROR(__xludf.DUMMYFUNCTION("""COMPUTED_VALUE"""),630369.2600000004) -> 630369.26 | D31: =IFERROR(__xludf.DUMMYFUNCTION("""COMPUTED_VALUE"""),52228.75000000013) -> 52228.75 | E31: =IFERROR(__xludf.DUMMYFUNCTION("""COMPUTED_VALUE"""),30366.989999999998) -> 30366.99 | F31: =IFERROR(__xludf.DUMMYFUNCTION("""COMPUTED_VALUE"""),9549.650000000009) -> 9549.65 | G31: =IFERROR(__xludf.DUMMYFUNCTION("""COMPUTED_VALUE"""),11514.040000000005) -> 11514.04
B32: =IFERROR(__xludf.DUMMYFUNCTION("""COMPUTED_VALUE"""),"eBay") -> eBay | C32: =IFERROR(__xludf.DUMMYFUNCTION("""COMPUTED_VALUE"""),45240.11999999946) -> 45240.12 | D32: =IFERROR(__xludf.DUMMYFUNCTION("""COMPUTED_VALUE"""),2195.1599999999985) -> 2195.16 | E32: =IFERROR(__xludf.DUMMYFUNCTION("""COMPUTED_VALUE"""),1249.9499999999998) -> 1249.95 | F32: =IFERROR(__xludf.DUMMYFUNCTION("""COMPUTED_VALUE"""),0.0) -> 0 | G32: =IFERROR(__xludf.DUMMYFUNCTION("""COMPUTED_VALUE"""),0.0) -> 0
B34: =IFERROR(__xludf.DUMMYFUNCTION("""COMPUTED_VALUE"""),"Sales") -> Sales | C34: =IFERROR(__xludf.DUMMYFUNCTION("""COMPUTED_VALUE"""),"Year to Date") -> Year to Date | D34: =IFERROR(__xludf.DUMMYFUNCTION("""COMPUTED_VALUE"""),"Last Month") -> Last Month | E34: =IFERROR(__xludf.DUMMYFUNCTION("""COMPUTED_VALUE"""),"Month to Date") -> Month to Date | F34: =IFERROR(__xludf.DUMMYFUNCTION("""COMPUTED_VALUE"""),"This Week") -> This Week | G34: =IFERROR(__xludf.DUMMYFUNCTION("""COMPUTED_VALUE"""),"Last Week") -> Last Week
C35: =IFERROR(__xludf.DUMMYFUNCTION("""COMPUTED_VALUE"""),2025.0) -> 2025 | D35: =IFERROR(__xludf.DUMMYFUNCTION("""COMPUTED_VALUE"""),"November") -> November | E35: =IFERROR(__xludf.DUMMYFUNCTION("""COMPUTED_VALUE"""),"December") -> December | F35: =IFERROR(__xludf.DUMMYFUNCTION("""COMPUTED_VALUE"""),45999.0) -> 45999 | G35: =IFERROR(__xludf.DUMMYFUNCTION("""COMPUTED_VALUE"""),45992.0) -> 45992
B36: =IFERROR(__xludf.DUMMYFUNCTION("""COMPUTED_VALUE"""),"All Vendors") -> All Vendors | C36: =IFERROR(__xludf.DUMMYFUNCTION("""COMPUTED_VALUE"""),1068091.0600000336) -> 1068091.1 | D36: =IFERROR(__xludf.DUMMYFUNCTION("""COMPUTED_VALUE"""),86933.69000000002) -> 86933.69 | E36: =IFERROR(__xludf.DUMMYFUNCTION("""COMPUTED_VALUE"""),50289.99000000002) -> 50289.99 | F36: =IFERROR(__xludf.DUMMYFUNCTION("""COMPUTED_VALUE"""),16071.940000000002) -> 16071.94 | G36: =IFERROR(__xludf.DUMMYFUNCTION("""COMPUTED_VALUE"""),18873.879999999997) -> 18873.88
B37: =IFERROR(__xludf.DUMMYFUNCTION("""COMPUTED_VALUE"""),"Keystone") -> Keystone | C37: =IFERROR(__xludf.DUMMYFUNCTION("""COMPUTED_VALUE"""),966647.7500000336) -> 966647.75 | D37: =IFERROR(__xludf.DUMMYFUNCTION("""COMPUTED_VALUE"""),81434.43000000002) -> 81434.43 | E37: =IFERROR(__xludf.DUMMYFUNCTION("""COMPUTED_VALUE"""),46648.080000000016) -> 46648.08 | F37: =IFERROR(__xludf.DUMMYFUNCTION("""COMPUTED_VALUE"""),14721.980000000003) -> 14721.98 | G37: =IFERROR(__xludf.DUMMYFUNCTION("""COMPUTED_VALUE"""),17865.629999999997) -> 17865.63
B38: =IFERROR(__xludf.DUMMYFUNCTION("""COMPUTED_VALUE"""),"eBay") -> eBay | C38: =IFERROR(__xludf.DUMMYFUNCTION("""COMPUTED_VALUE"""),85039.07000000002) -> 85039.07 | D38: =IFERROR(__xludf.DUMMYFUNCTION("""COMPUTED_VALUE"""),4787.340000000001) -> 4787.34 | E38: =IFERROR(__xludf.DUMMYFUNCTION("""COMPUTED_VALUE"""),2609.1899999999996) -> 2609.19 | F38: =IFERROR(__xludf.DUMMYFUNCTION("""COMPUTED_VALUE"""),1037.14) -> 1037.14 | G38: =IFERROR(__xludf.DUMMYFUNCTION("""COMPUTED_VALUE"""),887.2099999999999) -> 887.21
B39: =IFERROR(__xludf.DUMMYFUNCTION("""COMPUTED_VALUE"""),"RR-FBA") -> RR-FBA | C39: =IFERROR(__xludf.DUMMYFUNCTION("""COMPUTED_VALUE"""),1057.3499999999997) -> 1057.35 | D39: =IFERROR(__xludf.DUMMYFUNCTION("""COMPUTED_VALUE"""),120.22) -> 120.22 | E39: =IFERROR(__xludf.DUMMYFUNCTION("""COMPUTED_VALUE"""),340.02000000000015) -> 340.02 | F39: =IFERROR(__xludf.DUMMYFUNCTION("""COMPUTED_VALUE"""),11.610000000000001) -> 11.61 | G39: =IFERROR(__xludf.DUMMYFUNCTION("""COMPUTED_VALUE"""),8.68) -> 8.68
B40: =IFERROR(__xludf.DUMMYFUNCTION("""COMPUTED_VALUE"""),"TAAS") -> TAAS | C40: =IFERROR(__xludf.DUMMYFUNCTION("""COMPUTED_VALUE"""),12863.00000000001) -> 12863 | D40: =IFERROR(__xludf.DUMMYFUNCTION("""COMPUTED_VALUE"""),373.78000000000003) -> 373.78 | E40: =IFERROR(__xludf.DUMMYFUNCTION("""COMPUTED_VALUE"""),363.08000000000004) -> 363.08 | F40: =IFERROR(__xludf.DUMMYFUNCTION("""COMPUTED_VALUE"""),156.46) -> 156.46 | G40: =IFERROR(__xludf.DUMMYFUNCTION("""COMPUTED_VALUE"""),78.23) -> 78.23
B41: =IFERROR(__xludf.DUMMYFUNCTION("""COMPUTED_VALUE"""),"Nomadic-FBA") -> Nomadic-FBA | C41: =IFERROR(__xludf.DUMMYFUNCTION("""COMPUTED_VALUE"""),2483.890000000004) -> 2483.89 | D41: =IFERROR(__xludf.DUMMYFUNCTION("""COMPUTED_VALUE"""),217.92000000000007) -> 217.92 | E41: =IFERROR(__xludf.DUMMYFUNCTION("""COMPUTED_VALUE"""),329.62) -> 329.62 | F41: =IFERROR(__xludf.DUMMYFUNCTION("""COMPUTED_VALUE"""),144.75000000000003) -> 144.75 | G41: =IFERROR(__xludf.DUMMYFUNCTION("""COMPUTED_VALUE"""),34.129999999999995) -> 34.13
B43: =IFERROR(__xludf.DUMMYFUNCTION("""COMPUTED_VALUE"""),"Ads and Campaigns") -> Ads and Campaigns

Sheet Fuel Rider
A1: =IFERROR(__xludf.DUMMYFUNCTION("importrange(""https://docs.google.com/spreadsheets/d/1Y6d-tsHrGT_CvoBmJr48T_mwL008Vv39bFCdDy1GMNk/edit?gid=907455009#gid=907455009"",""FuelRider"")"),"") | B1: =IFERROR(__xludf.DUMMYFUNCTION("""COMPUTED_VALUE"""),"FR Supply Profitability Report") -> FR Supply Profitability Report
B2: =IFERROR(__xludf.DUMMYFUNCTION("""COMPUTED_VALUE"""),"Net Margins") -> Net Margins | C2: =IFERROR(__xludf.DUMMYFUNCTION("""COMPUTED_VALUE"""),"Year to Date") -> Year to Date | D2: =IFERROR(__xludf.DUMMYFUNCTION("""COMPUTED_VALUE"""),"Last Month") -> Last Month | E2: =IFERROR(__xludf.DUMMYFUNCTION("""COMPUTED_VALUE"""),"Month to Date") -> Month to Date | F2: =IFERROR(__xludf.DUMMYFUNCTION("""COMPUTED_VALUE"""),"This Week") -> This Week | G2: =IFERROR(__xludf.DUMMYFUNCTION("""COMPUTED_VALUE"""),"Last Week") -> Last Week
C3: =IFERROR(__xludf.DUMMYFUNCTION("""COMPUTED_VALUE"""),2025.0) -> 2025 | D3: =IFERROR(__xludf.DUMMYFUNCTION("""COMPUTED_VALUE"""),"November") -> November | E3: =IFERROR(__xludf.DUMMYFUNCTION("""COMPUTED_VALUE"""),"December") -> December | F3: =IFERROR(__xludf.DUMMYFUNCTION("""COMPUTED_VALUE"""),45999.0) -> 45999 | G3: =IFERROR(__xludf.DUMMYFUNCTION("""COMPUTED_VALUE"""),45992.0) -> 45992
B4: =IFERROR(__xludf.DUMMYFUNCTION("""COMPUTED_VALUE"""),"20% Projection") -> 20% Projection | C4: =IFERROR(__xludf.DUMMYFUNCTION("""COMPUTED_VALUE"""),14929.410000000047) -> 14929.41 | D4: =IFERROR(__xludf.DUMMYFUNCTION("""COMPUTED_VALUE"""),-111.05200000000005) -> -111.052 | E4: =IFERROR(__xludf.DUMMYFUNCTION("""COMPUTED_VALUE"""),-20.590000000000057) -> -20.59 | F4: =IFERROR(__xludf.DUMMYFUNCTION("""COMPUTED_VALUE"""),-174.74399999999997) -> -174.744 | G4: =IFERROR(__xludf.DUMMYFUNCTION("""COMPUTED_VALUE"""),-280.21400000000006) -> -280.214
B5: =IFERROR(__xludf.DUMMYFUNCTION("""COMPUTED_VALUE"""),"Net Profit Al's Supply") -> Net Profit Al's Supply | C5: =IFERROR(__xludf.DUMMYFUNCTION("""COMPUTED_VALUE"""),74647.05000000024) -> 74647.05 | D5: =IFERROR(__xludf.DUMMYFUNCTION("""COMPUTED_VALUE"""),-555.2600000000002) -> -555.26 | E5: =IFERROR(__xludf.DUMMYFUNCTION("""COMPUTED_VALUE"""),-102.95000000000027) -> -102.95 | F5: =IFERROR(__xludf.DUMMYFUNCTION("""COMPUTED_VALUE"""),-873.7199999999998) -> -873.72 | G5: =IFERROR(__xludf.DUMMYFUNCTION("""COMPUTED_VALUE"""),-1401.0700000000002) -> -1401.07
B6: =IFERROR(__xludf.DUMMYFUNCTION("""COMPUTED_VALUE"""),"Item Profit Vs. Returned Items") -> Item Profit Vs. Returned Items | C6: =IFERROR(__xludf.DUMMYFUNCTION("""COMPUTED_VALUE"""),84548.82000000024) -> 84548.82 | D6: =IFERROR(__xludf.DUMMYFUNCTION("""COMPUTED_VALUE"""),1390.8799999999997) -> 1390.88 | E6: =IFERROR(__xludf.DUMMYFUNCTION("""COMPUTED_VALUE"""),1585.1599999999999) -> 1585.16 | F6: =IFERROR(__xludf.DUMMYFUNCTION("""COMPUTED_VALUE"""),374.17) -> 374.17 | G6: =IFERROR(__xludf.DUMMYFUNCTION("""COMPUTED_VALUE"""),268.52) -> 268.52
B7: =IFERROR(__xludf.DUMMYFUNCTION("""COMPUTED_VALUE"""),"Al's Supply Item Sales Profit") -> Al's Supply Item Sales Profit | C7: =IFERROR(__xludf.DUMMYFUNCTION("""COMPUTED_VALUE"""),99013.83000000025) -> 99013.83 | D7: =IFERROR(__xludf.DUMMYFUNCTION("""COMPUTED_VALUE"""),1649.1099999999997) -> 1649.11 | E7: =IFERROR(__xludf.DUMMYFUNCTION("""COMPUTED_VALUE"""),1680.6799999999998) -> 1680.68 | F7: =IFERROR(__xludf.DUMMYFUNCTION("""COMPUTED_VALUE"""),395.0) -> 395 | G7: =IFERROR(__xludf.DUMMYFUNCTION("""COMPUTED_VALUE"""),310.66999999999996) -> 310.67
B8: =IFERROR(__xludf.DUMMYFUNCTION("""COMPUTED_VALUE"""),"Keystone") -> Keystone | C8: =IFERROR(__xludf.DUMMYFUNCTION("""COMPUTED_VALUE"""),91768.29000000024) -> 91768.29 | D8: =IFERROR(__xludf.DUMMYFUNCTION("""COMPUTED_VALUE"""),1448.5999999999997) -> 1448.6 | E8: =IFERROR(__xludf.DUMMYFUNCTION("""COMPUTED_VALUE"""),1407.54) -> 1407.54 | F8: =IFERROR(__xludf.DUMMYFUNCTION("""COMPUTED_VALUE"""),337.56) -> 337.56 | G8: =IFERROR(__xludf.DUMMYFUNCTION("""COMPUTED_VALUE"""),218.0) -> 218
B9: =IFERROR(__xludf.DUMMYFUNCTION("""COMPUTED_VALUE"""),"eBay") -> eBay | C9: =IFERROR(__xludf.DUMMYFUNCTION("""COMPUTED_VALUE"""),120.95999999999998) -> 120.96 | D9: =IFERROR(__xludf.DUMMYFUNCTION("""COMPUTED_VALUE"""),22.769999999999996) -> 22.77 | E9: =IFERROR(__xludf.DUMMYFUNCTION("""COMPUTED_VALUE"""),0.0) -> 0 | F9: =IFERROR(__xludf.DUMMYFUNCTION("""COMPUTED_VALUE"""),0.0) -> 0 | G9: =IFERROR(__xludf.DUMMYFUNCTION("""COMPUTED_VALUE"""),22.769999999999996) -> 22.77
B10: =IFERROR(__xludf.DUMMYFUNCTION("""COMPUTED_VALUE"""),"TAAS") -> TAAS | C10: =IFERROR(__xludf.DUMMYFUNCTION("""COMPUTED_VALUE"""),1977.0400000000004) -> 1977.04 | D10: =IFERROR(__xludf.DUMMYFUNCTION("""COMPUTED_VALUE"""),0.0) -> 0 | E10: =IFERROR(__xludf.DUMMYFUNCTION("""COMPUTED_VALUE"""),0.0) -> 0 | F10: =IFERROR(__xludf.DUMMYFUNCTION("""COMPUTED_VALUE"""),0.0) -> 0 | G10: =IFERROR(__xludf.DUMMYFUNCTION("""COMPUTED_VALUE"""),0.0) -> 0
B11: =IFERROR(__xludf.DUMMYFUNCTION("""COMPUTED_VALUE"""),"RR-Wally's") -> RR-Wally's | C11: =IFERROR(__xludf.DUMMYFUNCTION("""COMPUTED_VALUE"""),4257.320000000013) -> 4257.32 | D11: =IFERROR(__xludf.DUMMYFUNCTION("""COMPUTED_VALUE"""),177.74) -> 177.74 | E11: =IFERROR(__xludf.DUMMYFUNCTION("""COMPUTED_VALUE"""),273.14) -> 273.14 | F11: =IFERROR(__xludf.DUMMYFUNCTION("""COMPUTED_VALUE"""),57.44) -> 57.44 | G11: =IFERROR(__xludf.DUMMYFUNCTION("""COMPUTED_VALUE"""),69.9) -> 69.9
B12: =IFERROR(__xludf.DUMMYFUNCTION("""COMPUTED_VALUE"""),"RR-FBA") -> RR-FBA | C12: =IFERROR(__xludf.DUMMYFUNCTION("""COMPUTED_VALUE"""),224.7299999999998) -> 224.73 | D12: =IFERROR(__xludf.DUMMYFUNCTION("""COMPUTED_VALUE"""),0.0) -> 0 | E12: =IFERROR(__xludf.DUMMYFUNCTION("""COMPUTED_VALUE"""),0.0) -> 0 | F12: =IFERROR(__xludf.DUMMYFUNCTION("""COMPUTED_VALUE"""),0.0) -> 0 | G12: =IFERROR(__xludf.DUMMYFUNCTION("""COMPUTED_VALUE"""),0.0) -> 0
B13: =IFERROR(__xludf.DUMMYFUNCTION("""COMPUTED_VALUE"""),"Returns-TAAS") -> Returns-TAAS | C13: =IFERROR(__xludf.DUMMYFUNCTION("""COMPUTED_VALUE"""),596.21) -> 596.21 | D13: =IFERROR(__xludf.DUMMYFUNCTION("""COMPUTED_VALUE"""),0.0) -> 0 | E13: =IFERROR(__xludf.DUMMYFUNCTION("""COMPUTED_VALUE"""),0.0) -> 0 | F13: =IFERROR(__xludf.DUMMYFUNCTION("""COMPUTED_VALUE"""),0.0) -> 0 | G13: =IFERROR(__xludf.DUMMYFUNCTION("""COMPUTED_VALUE"""),0.0) -> 0
B14: =IFERROR(__xludf.DUMMYFUNCTION("""COMPUTED_VALUE"""),"Returns - Rico") -> Returns - Rico | C14: =IFERROR(__xludf.DUMMYFUNCTION("""COMPUTED_VALUE"""),69.28) -> 69.28 | D14: =IFERROR(__xludf.DUMMYFUNCTION("""COMPUTED_VALUE"""),0.0) -> 0 | E14: =IFERROR(__xludf.DUMMYFUNCTION("""COMPUTED_VALUE"""),0.0) -> 0 | F14: =IFERROR(__xludf.DUMMYFUNCTION("""COMPUTED_VALUE"""),0.0) -> 0 | G14: =IFERROR(__xludf.DUMMYFUNCTION("""COMPUTED_VALUE"""),0.0) -> 0
B16: =IFERROR(__xludf.DUMMYFUNCTION("""COMPUTED_VALUE"""),"Returns") -> Returns | C16: =IFERROR(__xludf.DUMMYFUNCTION("""COMPUTED_VALUE"""),-14465.010000000013) -> -14465.01 | D16: =IFERROR(__xludf.DUMMYFUNCTION("""COMPUTED_VALUE"""),-258.22999999999996) -> -258.23 | E16: =IFERROR(__xludf.DUMMYFUNCTION("""COMPUTED_VALUE"""),-95.52) -> -95.52 | F16: =IFERROR(__xludf.DUMMYFUNCTION("""COMPUTED_VALUE"""),-20.83) -> -20.83 | G16: =IFERROR(__xludf.DUMMYFUNCTION("""COMPUTED_VALUE"""),-42.15) -> -42.15
B17: =IFERROR(__xludf.DUMMYFUNCTION("""COMPUTED_VALUE"""),"Keystone") -> Keystone | C17: =IFERROR(__xludf.DUMMYFUNCTION("""COMPUTED_VALUE"""),-14131.850000000013) -> -14131.85 | D17: =IFERROR(__xludf.DUMMYFUNCTION("""COMPUTED_VALUE"""),-258.22999999999996) -> -258.23 | E17: =IFERROR(__xludf.DUMMYFUNCTION("""COMPUTED_VALUE"""),-83.52) -> -83.52 | F17: =IFERROR(__xludf.DUMMYFUNCTION("""COMPUTED_VALUE"""),-14.83) -> -14.83 | G17: =IFERROR(__xludf.DUMMYFUNCTION("""COMPUTED_VALUE"""),-42.15) -> -42.15
B18: =IFERROR(__xludf.DUMMYFUNCTION("""COMPUTED_VALUE"""),"eBay") -> eBay | C18: =IFERROR(__xludf.DUMMYFUNCTION("""COMPUTED_VALUE"""),-19.98) -> -19.98 | D18: =IFERROR(__xludf.DUMMYFUNCTION("""COMPUTED_VALUE"""),0.0) -> 0 | E18: =IFERROR(__xludf.DUMMYFUNCTION("""COMPUTED_VALUE"""),0.0) -> 0 | F18: =IFERROR(__xludf.DUMMYFUNCTION("""COMPUTED_VALUE"""),0.0) -> 0 | G18: =IFERROR(__xludf.DUMMYFUNCTION("""COMPUTED_VALUE"""),0.0) -> 0
B19: =IFERROR(__xludf.DUMMYFUNCTION("""COMPUTED_VALUE"""),"TAAS") -> TAAS | C19: =IFERROR(__xludf.DUMMYFUNCTION("""COMPUTED_VALUE"""),-82.18) -> -82.18 | D19: =IFERROR(__xludf.DUMMYFUNCTION("""COMPUTED_VALUE"""),0.0) -> 0 | E19: =IFERROR(__xludf.DUMMYFUNCTION("""COMPUTED_VALUE"""),0.0) -> 0 | F19: =IFERROR(__xludf.DUMMYFUNCTION("""COMPUTED_VALUE"""),0.0) -> 0 | G19: =IFERROR(__xludf.DUMMYFUNCTION("""COMPUTED_VALUE"""),0.0) -> 0
B20: =IFERROR(__xludf.DUMMYFUNCTION("""COMPUTED_VALUE"""),"RR-Wally's") -> RR-Wally's | C20: =IFERROR(__xludf.DUMMYFUNCTION("""COMPUTED_VALUE"""),-174.0) -> -174 | D20: =IFERROR(__xludf.DUMMYFUNCTION("""COMPUTED_VALUE"""),0.0) -> 0 | E20: =IFERROR(__xludf.DUMMYFUNCTION("""COMPUTED_VALUE"""),-12.0) -> -12 | F20: =IFERROR(__xludf.DUMMYFUNCTION("""COMPUTED_VALUE"""),-6.0) -> -6 | G20: =IFERROR(__xludf.DUMMYFUNCTION("""COMPUTED_VALUE"""),0.0) -> 0
B21: =IFERROR(__xludf.DUMMYFUNCTION("""COMPUTED_VALUE"""),"RR-FBA") -> RR-FBA | C21: =IFERROR(__xludf.DUMMYFUNCTION("""COMPUTED_VALUE"""),-7.0) -> -7 | D21: =IFERROR(__xludf.DUMMYFUNCTION("""COMPUTED_VALUE"""),0.0) -> 0 | E21: =IFERROR(__xludf.DUMMYFUNCTION("""COMPUTED_VALUE"""),0.0) -> 0 | F21: =IFERROR(__xludf.DUMMYFUNCTION("""COMPUTED_VALUE"""),0.0) -> 0 | G21: =IFERROR(__xludf.DUMMYFUNCTION("""COMPUTED_VALUE"""),0.0) -> 0
B22: =IFERROR(__xludf.DUMMYFUNCTION("""COMPUTED_VALUE"""),"Returns-TAAS") -> Returns-TAAS | C22: =IFERROR(__xludf.DUMMYFUNCTION("""COMPUTED_VALUE"""),-50.0) -> -50 | D22: =IFERROR(__xludf.DUMMYFUNCTION("""COMPUTED_VALUE"""),0.0) -> 0 | E22: =IFERROR(__xludf.DUMMYFUNCTION("""COMPUTED_VALUE"""),0.0) -> 0 | F22: =IFERROR(__xludf.DUMMYFUNCTION("""COMPUTED_VALUE"""),0.0) -> 0 | G22: =IFERROR(__xludf.DUMMYFUNCTION("""COMPUTED_VALUE"""),0.0) -> 0
B23: =IFERROR(__xludf.DUMMYFUNCTION("""COMPUTED_VALUE"""),"Returns - Rico") -> Returns - Rico | C23: =IFERROR(__xludf.DUMMYFUNCTION("""COMPUTED_VALUE"""),0.0) -> 0 | D23: =IFERROR(__xludf.DUMMYFUNCTION("""COMPUTED_VALUE"""),0.0) -> 0 | E23: =IFERROR(__xludf.DUMMYFUNCTION("""COMPUTED_VALUE"""),0.0) -> 0 | F23: =IFERROR(__xludf.DUMMYFUNCTION("""COMPUTED_VALUE"""),0.0) -> 0 | G23: =IFERROR(__xludf.DUMMYFUNCTION("""COMPUTED_VALUE"""),0.0) -> 0
B25: =IFERROR(__xludf.DUMMYFUNCTION("""COMPUTED_VALUE"""),"Other Fees") -> Other Fees | C25: =IFERROR(__xludf.DUMMYFUNCTION("""COMPUTED_VALUE"""),-9901.770000000002) -> -9901.77 | D25: =IFERROR(__xludf.DUMMYFUNCTION("""COMPUTED_VALUE"""),-1946.14) -> -1946.14 | E25: =IFERROR(__xludf.DUMMYFUNCTION("""COMPUTED_VALUE"""),-1688.1100000000001) -> -1688.11 | F25: =IFERROR(__xludf.DUMMYFUNCTION("""COMPUTED_VALUE"""),-1247.8899999999999) -> -1247.89 | G25: =IFERROR(__xludf.DUMMYFUNCTION("""COMPUTED_VALUE"""),-1669.5900000000001) -> -1669.59
B26: =IFERROR(__xludf.DUMMYFUNCTION("""COMPUTED_VALUE"""),"Shipping Services") -> Shipping Services | C26: =IFERROR(__xludf.DUMMYFUNCTION("""COMPUTED_VALUE"""),-5570.830000000003) -> -5570.83 | D26: =IFERROR(__xludf.DUMMYFUNCTION("""COMPUTED_VALUE"""),-269.04999999999995) -> -269.05 | E26: =IFERROR(__xludf.DUMMYFUNCTION("""COMPUTED_VALUE"""),-116.75999999999999) -> -116.76 | F26: =IFERROR(__xludf.DUMMYFUNCTION("""COMPUTED_VALUE"""),-27.739999999999995) -> -27.74 | G26: =IFERROR(__xludf.DUMMYFUNCTION("""COMPUTED_VALUE"""),-97.44999999999999) -> -97.45
B27: =IFERROR(__xludf.DUMMYFUNCTION("""COMPUTED_VALUE"""),"FBA Inventory Fee") -> FBA Inventory Fee | C27: =IFERROR(__xludf.DUMMYFUNCTION("""COMPUTED_VALUE"""),-338.26) -> -338.26 | D27: =IFERROR(__xludf.DUMMYFUNCTION("""COMPUTED_VALUE"""),0.0) -> 0 | E27: =IFERROR(__xludf.DUMMYFUNCTION("""COMPUTED_VALUE"""),-288.11) -> -288.11 | F27: =IFERROR(__xludf.DUMMYFUNCTION("""COMPUTED_VALUE"""),-288.11) -> -288.11 | G27: =IFERROR(__xludf.DUMMYFUNCTION("""COMPUTED_VALUE"""),0.0) -> 0
B28: =IFERROR(__xludf.DUMMYFUNCTION("""COMPUTED_VALUE"""),"Service Fee") -> Service Fee | C28: =IFERROR(__xludf.DUMMYFUNCTION("""COMPUTED_VALUE"""),-3918.95) -> -3918.95 | D28: =IFERROR(__xludf.DUMMYFUNCTION("""COMPUTED_VALUE"""),-1677.0900000000001) -> -1677.09 | E28: =IFERROR(__xludf.DUMMYFUNCTION("""COMPUTED_VALUE"""),-1283.24) -> -1283.24 | F28: =IFERROR(__xludf.DUMMYFUNCTION("""COMPUTED_VALUE"""),-932.04) -> -932.04 | G28: =IFERROR(__xludf.DUMMYFUNCTION("""COMPUTED_VALUE"""),-1572.14) -> -1572.14
B29: =IFERROR(__xludf.DUMMYFUNCTION("""COMPUTED_VALUE"""),"SAFE-T reimbursement") -> SAFE-T reimbursement | C29: =IFERROR(__xludf.DUMMYFUNCTION("""COMPUTED_VALUE"""),182.93) -> 182.93 | D29: =IFERROR(__xludf.DUMMYFUNCTION("""COMPUTED_VALUE"""),0.0) -> 0 | E29: =IFERROR(__xludf.DUMMYFUNCTION("""COMPUTED_VALUE"""),0.0) -> 0 | F29: =IFERROR(__xludf.DUMMYFUNCTION("""COMPUTED_VALUE"""),0.0) -> 0 | G29: =IFERROR(__xludf.DUMMYFUNCTION("""COMPUTED_VALUE"""),0.0) -> 0
B30: =IFERROR(__xludf.DUMMYFUNCTION("""COMPUTED_VALUE"""),"Liquidations Adjustments") -> Liquidations Adjustments | C30: =IFERROR(__xludf.DUMMYFUNCTION("""COMPUTED_VALUE"""),0.0) -> 0 | D30: =IFERROR(__xludf.DUMMYFUNCTION("""COMPUTED_VALUE"""),0.0) -> 0 | E30: =IFERROR(__xludf.DUMMYFUNCTION("""COMPUTED_VALUE"""),0.0) -> 0 | F30: =IFERROR(__xludf.DUMMYFUNCTION("""COMPUTED_VALUE"""),0.0) -> 0 | G30: =IFERROR(__xludf.DUMMYFUNCTION("""COMPUTED_VALUE"""),0.0) -> 0
B31: =IFERROR(__xludf.DUMMYFUNCTION("""COMPUTED_VALUE"""),"Adjustment") -> Adjustment | C31: =IFERROR(__xludf.DUMMYFUNCTION("""COMPUTED_VALUE"""),0.7600000000000002) -> 0.76 | D31: =IFERROR(__xludf.DUMMYFUNCTION("""COMPUTED_VALUE"""),0.0) -> 0 | E31: =IFERROR(__xludf.DUMMYFUNCTION("""COMPUTED_VALUE"""),0.0) -> 0 | F31: =IFERROR(__xludf.DUMMYFUNCTION("""COMPUTED_VALUE"""),0.0) -> 0 | G31: =IFERROR(__xludf.DUMMYFUNCTION("""COMPUTED_VALUE"""),0.0) -> 0
B32: =IFERROR(__xludf.DUMMYFUNCTION("""COMPUTED_VALUE"""),"A-to-z Guarantee Claim") -> A-to-z Guarantee Claim | C32: =IFERROR(__xludf.DUMMYFUNCTION("""COMPUTED_VALUE"""),-257.42) -> -257.42 | D32: =IFERROR(__xludf.DUMMYFUNCTION("""COMPUTED_VALUE"""),0.0) -> 0 | E32: =IFERROR(__xludf.DUMMYFUNCTION("""COMPUTED_VALUE"""),0.0) -> 0 | F32: =IFERROR(__xludf.DUMMYFUNCTION("""COMPUTED_VALUE"""),0.0) -> 0 | G32: =IFERROR(__xludf.DUMMYFUNCTION("""COMPUTED_VALUE"""),0.0) -> 0
B34: =IFERROR(__xludf.DUMMYFUNCTION("""COMPUTED_VALUE"""),"Purchase Reconciliations") -> Purchase Reconciliations
B35: =IFERROR(__xludf.DUMMYFUNCTION("""COMPUTED_VALUE"""),"Keystone") -> Keystone | C35: =IFERROR(__xludf.DUMMYFUNCTION("""COMPUTED_VALUE"""),145839.33000000002) -> 145839.33 | D35: =IFERROR(__xludf.DUMMYFUNCTION("""COMPUTED_VALUE"""),2939.42) -> 2939.42 | E35: =IFERROR(__xludf.DUMMYFUNCTION("""COMPUTED_VALUE"""),1746.6599999999999) -> 1746.66 | F35: =IFERROR(__xludf.DUMMYFUNCTION("""COMPUTED_VALUE"""),549.46) -> 549.46 | G35: =IFERROR(__xludf.DUMMYFUNCTION("""COMPUTED_VALUE"""),358.55999999999995) -> 358.56
B36: =IFERROR(__xludf.DUMMYFUNCTION("""COMPUTED_VALUE"""),"eBay") -> eBay | C36: =IFERROR(__xludf.DUMMYFUNCTION("""COMPUTED_VALUE"""),265.7800000000001) -> 265.78 | D36: =IFERROR(__xludf.DUMMYFUNCTION("""COMPUTED_VALUE"""),29.97) -> 29.97 | E36: =IFERROR(__xludf.DUMMYFUNCTION("""COMPUTED_VALUE"""),0.0) -> 0 | F36: =IFERROR(__xludf.DUMMYFUNCTION("""COMPUTED_VALUE"""),0.0) -> 0 | G36: =IFERROR(__xludf.DUMMYFUNCTION("""COMPUTED_VALUE"""),0.0) -> 0
B38: =IFERROR(__xludf.DUMMYFUNCTION("""COMPUTED_VALUE"""),"Sales") -> Sales | C38: =IFERROR(__xludf.DUMMYFUNCTION("""COMPUTED_VALUE"""),"Year to Date") -> Year to Date | D38: =IFERROR(__xludf.DUMMYFUNCTION("""COMPUTED_VALUE"""),"Last Month") -> Last Month | E38: =IFERROR(__xludf.DUMMYFUNCTION("""COMPUTED_VALUE"""),"Month to Date") -> Month to Date | F38: =IFERROR(__xludf.DUMMYFUNCTION("""COMPUTED_VALUE"""),"This Week") -> This Week | G38: =IFERROR(__xludf.DUMMYFUNCTION("""COMPUTED_VALUE"""),"Last Week") -> Last Week
C39: =IFERROR(__xludf.DUMMYFUNCTION("""COMPUTED_VALUE"""),2025.0) -> 2025 | D39: =IFERROR(__xludf.DUMMYFUNCTION("""COMPUTED_VALUE"""),"November") -> November | E39: =IFERROR(__xludf.DUMMYFUNCTION("""COMPUTED_VALUE"""),"December") -> December | F39: =IFERROR(__xludf.DUMMYFUNCTION("""COMPUTED_VALUE"""),45999.0) -> 45999 | G39: =IFERROR(__xludf.DUMMYFUNCTION("""COMPUTED_VALUE"""),45992.0) -> 45992
B40: =IFERROR(__xludf.DUMMYFUNCTION("""COMPUTED_VALUE"""),"All Vendors") -> All Vendors | C40: =IFERROR(__xludf.DUMMYFUNCTION("""COMPUTED_VALUE"""),248984.1999999986) -> 248984.2 | D40: =IFERROR(__xludf.DUMMYFUNCTION("""COMPUTED_VALUE"""),4660.5) -> 4660.5 | E40: =IFERROR(__xludf.DUMMYFUNCTION("""COMPUTED_VALUE"""),3487.3399999999983) -> 3487.34 | F40: =IFERROR(__xludf.DUMMYFUNCTION("""COMPUTED_VALUE"""),956.46) -> 956.46 | G40: =IFERROR(__xludf.DUMMYFUNCTION("""COMPUTED_VALUE"""),717.2) -> 717.2
B41: =IFERROR(__xludf.DUMMYFUNCTION("""COMPUTED_VALUE"""),"Keystone") -> Keystone | C41: =IFERROR(__xludf.DUMMYFUNCTION("""COMPUTED_VALUE"""),237607.6199999986) -> 237607.62 | D41: =IFERROR(__xludf.DUMMYFUNCTION("""COMPUTED_VALUE"""),4388.02) -> 4388.02 | E41: =IFERROR(__xludf.DUMMYFUNCTION("""COMPUTED_VALUE"""),3154.1999999999985) -> 3154.2 | F41: =IFERROR(__xludf.DUMMYFUNCTION("""COMPUTED_VALUE"""),887.02) -> 887.02 | G41: =IFERROR(__xludf.DUMMYFUNCTION("""COMPUTED_VALUE"""),576.5600000000001) -> 576.56
B42: =IFERROR(__xludf.DUMMYFUNCTION("""COMPUTED_VALUE"""),"eBay") -> eBay | C42: =IFERROR(__xludf.DUMMYFUNCTION("""COMPUTED_VALUE"""),386.7399999999998) -> 386.74 | D42: =IFERROR(__xludf.DUMMYFUNCTION("""COMPUTED_VALUE"""),52.739999999999995) -> 52.74 | E42: =IFERROR(__xludf.DUMMYFUNCTION("""COMPUTED_VALUE"""),0.0) -> 0 | F42: =IFERROR(__xludf.DUMMYFUNCTION("""COMPUTED_VALUE"""),0.0) -> 0 | G42: =IFERROR(__xludf.DUMMYFUNCTION("""COMPUTED_VALUE"""),52.739999999999995) -> 52.74
B43: =IFERROR(__xludf.DUMMYFUNCTION("""COMPUTED_VALUE"""),"TAAS") -> TAAS | C43: =IFERROR(__xludf.DUMMYFUNCTION("""COMPUTED_VALUE"""),3838.2999999999975) -> 3838.3 | D43: =IFERROR(__xludf.DUMMYFUNCTION("""COMPUTED_VALUE"""),0.0) -> 0 | E43: =IFERROR(__xludf.DUMMYFUNCTION("""COMPUTED_VALUE"""),0.0) -> 0 | F43: =IFERROR(__xludf.DUMMYFUNCTION("""COMPUTED_VALUE"""),0.0) -> 0 | G43: =IFERROR(__xludf.DUMMYFUNCTION("""COMPUTED_VALUE"""),0.0) -> 0
B44: =IFERROR(__xludf.DUMMYFUNCTION("""COMPUTED_VALUE"""),"RR-Wally's") -> RR-Wally's | C44: =IFERROR(__xludf.DUMMYFUNCTION("""COMPUTED_VALUE"""),5938.319999999994) -> 5938.32 | D44: =IFERROR(__xludf.DUMMYFUNCTION("""COMPUTED_VALUE"""),219.74) -> 219.74 | E44: =IFERROR(__xludf.DUMMYFUNCTION("""COMPUTED_VALUE"""),333.14) -> 333.14 | F44: =IFERROR(__xludf.DUMMYFUNCTION("""COMPUTED_VALUE"""),69.44) -> 69.44 | G44: =IFERROR(__xludf.DUMMYFUNCTION("""COMPUTED_VALUE"""),87.89999999999999) -> 87.9
...

Sheet SOT
A1: =IFERROR(__xludf.DUMMYFUNCTION("importrange(""https://docs.google.com/spreadsheets/d/1S3MX3cHqFIgb4SzkDH9lXORTMiEkDw5ybW1ovrknbRg/edit?gid=907455009#gid=907455009"",""SOT"")"),"") | B1: =IFERROR(__xludf.DUMMYFUNCTION("""COMPUTED_VALUE"""),"Al's Supply Profitability Report") -> Al's Supply Profitability Report
B2: =IFERROR(__xludf.DUMMYFUNCTION("""COMPUTED_VALUE"""),"Net Margins") -> Net Margins | C2: =IFERROR(__xludf.DUMMYFUNCTION("""COMPUTED_VALUE"""),"Year to Date") -> Year to Date | D2: =IFERROR(__xludf.DUMMYFUNCTION("""COMPUTED_VALUE"""),"Last Month") -> Last Month | E2: =IFERROR(__xludf.DUMMYFUNCTION("""COMPUTED_VALUE"""),"Month to Date") -> Month to Date | F2: =IFERROR(__xludf.DUMMYFUNCTION("""COMPUTED_VALUE"""),"This Week") -> This Week | G2: =IFERROR(__xludf.DUMMYFUNCTION("""COMPUTED_VALUE"""),"Last Week") -> Last Week
C3: =IFERROR(__xludf.DUMMYFUNCTION("""COMPUTED_VALUE"""),2025.0) -> 2025 | D3: =IFERROR(__xludf.DUMMYFUNCTION("""COMPUTED_VALUE"""),"November") -> November | E3: =IFERROR(__xludf.DUMMYFUNCTION("""COMPUTED_VALUE"""),"December") -> December | F3: =IFERROR(__xludf.DUMMYFUNCTION("""COMPUTED_VALUE"""),45999.0) -> 45999 | G3: =IFERROR(__xludf.DUMMYFUNCTION("""COMPUTED_VALUE"""),45992.0) -> 45992
B4: =IFERROR(__xludf.DUMMYFUNCTION("""COMPUTED_VALUE"""),"20% Projection") -> 20% Projection | C4: =IFERROR(__xludf.DUMMYFUNCTION("""COMPUTED_VALUE"""),61.77999999999957) -> 61.78 | D4: =IFERROR(__xludf.DUMMYFUNCTION("""COMPUTED_VALUE"""),-40.852000000000004) -> -40.852 | E4: =IFERROR(__xludf.DUMMYFUNCTION("""COMPUTED_VALUE"""),-42.312000000000005) -> -42.312 | F4: =IFERROR(__xludf.DUMMYFUNCTION("""COMPUTED_VALUE"""),-18.364) -> -18.364 | G4: =IFERROR(__xludf.DUMMYFUNCTION("""COMPUTED_VALUE"""),-5.334) -> -5.334
B5: =IFERROR(__xludf.DUMMYFUNCTION("""COMPUTED_VALUE"""),"Net Profit Al's Supply") -> Net Profit Al's Supply | C5: =IFERROR(__xludf.DUMMYFUNCTION("""COMPUTED_VALUE"""),308.8999999999978) -> 308.9 | D5: =IFERROR(__xludf.DUMMYFUNCTION("""COMPUTED_VALUE"""),-204.26) -> -204.26 | E5: =IFERROR(__xludf.DUMMYFUNCTION("""COMPUTED_VALUE"""),-211.56) -> -211.56 | F5: =IFERROR(__xludf.DUMMYFUNCTION("""COMPUTED_VALUE"""),-91.82000000000001) -> -91.82 | G5: =IFERROR(__xludf.DUMMYFUNCTION("""COMPUTED_VALUE"""),-26.669999999999998) -> -26.67
B6: =IFERROR(__xludf.DUMMYFUNCTION("""COMPUTED_VALUE"""),"Item Profit Vs. Returned Items") -> Item Profit Vs. Returned Items | C6: =IFERROR(__xludf.DUMMYFUNCTION("""COMPUTED_VALUE"""),2684.529999999997) -> 2684.53 | D6: =IFERROR(__xludf.DUMMYFUNCTION("""COMPUTED_VALUE"""),-71.64) -> -71.64 | E6: =IFERROR(__xludf.DUMMYFUNCTION("""COMPUTED_VALUE"""),-127.65) -> -127.65 | F6: =IFERROR(__xludf.DUMMYFUNCTION("""COMPUTED_VALUE"""),-26.01) -> -26.01 | G6: =IFERROR(__xludf.DUMMYFUNCTION("""COMPUTED_VALUE"""),0.0) -> 0
B7: =IFERROR(__xludf.DUMMYFUNCTION("""COMPUTED_VALUE"""),"Al's Supply Item Sales Profit") -> Al's Supply Item Sales Profit | C7: =IFERROR(__xludf.DUMMYFUNCTION("""COMPUTED_VALUE"""),5606.619999999999) -> 5606.62 | D7: =IFERROR(__xludf.DUMMYFUNCTION("""COMPUTED_VALUE"""),0.0) -> 0 | E7: =IFERROR(__xludf.DUMMYFUNCTION("""COMPUTED_VALUE"""),0.0) -> 0 | F7: =IFERROR(__xludf.DUMMYFUNCTION("""COMPUTED_VALUE"""),0.0) -> 0 | G7: =IFERROR(__xludf.DUMMYFUNCTION("""COMPUTED_VALUE"""),0.0) -> 0
B8: =IFERROR(__xludf.DUMMYFUNCTION("""COMPUTED_VALUE"""),"Keystone") -> Keystone | C8: =IFERROR(__xludf.DUMMYFUNCTION("""COMPUTED_VALUE"""),5216.8099999999995) -> 5216.81 | D8: =IFERROR(__xludf.DUMMYFUNCTION("""COMPUTED_VALUE"""),0.0) -> 0 | E8: =IFERROR(__xludf.DUMMYFUNCTION("""COMPUTED_VALUE"""),0.0) -> 0 | F8: =IFERROR(__xludf.DUMMYFUNCTION("""COMPUTED_VALUE"""),0.0) -> 0 | G8: =IFERROR(__xludf.DUMMYFUNCTION("""COMPUTED_VALUE"""),0.0) -> 0
B9: =IFERROR(__xludf.DUMMYFUNCTION("""COMPUTED_VALUE"""),"eBay") -> eBay | C9: =IFERROR(__xludf.DUMMYFUNCTION("""COMPUTED_VALUE"""),299.29000000000013) -> 299.29 | D9: =IFERROR(__xludf.DUMMYFUNCTION("""COMPUTED_VALUE"""),0.0) -> 0 | E9: =IFERROR(__xludf.DUMMYFUNCTION("""COMPUTED_VALUE"""),0.0) -> 0 | F9: =IFERROR(__xludf.DUMMYFUNCTION("""COMPUTED_VALUE"""),0.0) -> 0 | G9: =IFERROR(__xludf.DUMMYFUNCTION("""COMPUTED_VALUE"""),0.0) -> 0
B10: =IFERROR(__xludf.DUMMYFUNCTION("""COMPUTED_VALUE"""),"TAAS") -> TAAS | C10: =IFERROR(__xludf.DUMMYFUNCTION("""COMPUTED_VALUE"""),97.28000000000002) -> 97.28 | D10: =IFERROR(__xludf.DUMMYFUNCTION("""COMPUTED_VALUE"""),0.0) -> 0 | E10: =IFERROR(__xludf.DUMMYFUNCTION("""COMPUTED_VALUE"""),0.0) -> 0 | F10: =IFERROR(__xludf.DUMMYFUNCTION("""COMPUTED_VALUE"""),0.0) -> 0 | G10: =IFERROR(__xludf.DUMMYFUNCTION("""COMPUTED_VALUE"""),0.0) -> 0 | L10: =IFERROR(__xludf.DUMMYFUNCTION("""COMPUTED_VALUE"""),360.0) -> 360
B11: =IFERROR(__xludf.DUMMYFUNCTION("""COMPUTED_VALUE"""),"RR-Wally's") -> RR-Wally's | C11: =IFERROR(__xludf.DUMMYFUNCTION("""COMPUTED_VALUE"""),0.0) -> 0 | D11: =IFERROR(__xludf.DUMMYFUNCTION("""COMPUTED_VALUE"""),0.0) -> 0 | E11: =IFERROR(__xludf.DUMMYFUNCTION("""COMPUTED_VALUE"""),0.0) -> 0 | F11: =IFERROR(__xludf.DUMMYFUNCTION("""COMPUTED_VALUE"""),0.0) -> 0 | G11: =IFERROR(__xludf.DUMMYFUNCTION("""COMPUTED_VALUE"""),0.0) -> 0 | L11: =IFERROR(__xludf.DUMMYFUNCTION("""COMPUTED_VALUE"""),720.0) -> 720
B12: =IFERROR(__xludf.DUMMYFUNCTION("""COMPUTED_VALUE"""),"RR-FBA") -> RR-FBA | C12: =IFERROR(__xludf.DUMMYFUNCTION("""COMPUTED_VALUE"""),-6.76) -> -6.76 | D12: =IFERROR(__xludf.DUMMYFUNCTION("""COMPUTED_VALUE"""),0.0) -> 0 | E12: =IFERROR(__xludf.DUMMYFUNCTION("""COMPUTED_VALUE"""),0.0) -> 0 | F12: =IFERROR(__xludf.DUMMYFUNCTION("""COMPUTED_VALUE"""),0.0) -> 0 | G12: =IFERROR(__xludf.DUMMYFUNCTION("""COMPUTED_VALUE"""),0.0) -> 0
B13: =IFERROR(__xludf.DUMMYFUNCTION("""COMPUTED_VALUE"""),"Returns-TAAS") -> Returns-TAAS | C13: =IFERROR(__xludf.DUMMYFUNCTION("""COMPUTED_VALUE"""),0.0) -> 0 | D13: =IFERROR(__xludf.DUMMYFUNCTION("""COMPUTED_VALUE"""),0.0) -> 0 | E13: =IFERROR(__xludf.DUMMYFUNCTION("""COMPUTED_VALUE"""),0.0) -> 0 | F13: =IFERROR(__xludf.DUMMYFUNCTION("""COMPUTED_VALUE"""),0.0) -> 0 | G13: =IFERROR(__xludf.DUMMYFUNCTION("""COMPUTED_VALUE"""),0.0) -> 0
B14: =IFERROR(__xludf.DUMMYFUNCTION("""COMPUTED_VALUE"""),"Returns - Rico") -> Returns - Rico | C14: =IFERROR(__xludf.DUMMYFUNCTION("""COMPUTED_VALUE"""),0.0) -> 0 | D14: =IFERROR(__xludf.DUMMYFUNCTION("""COMPUTED_VALUE"""),0.0) -> 0 | E14: =IFERROR(__xludf.DUMMYFUNCTION("""COMPUTED_VALUE"""),0.0) -> 0 | F14: =IFERROR(__xludf.DUMMYFUNCTION("""COMPUTED_VALUE"""),0.0) -> 0 | G14: =IFERROR(__xludf.DUMMYFUNCTION("""COMPUTED_VALUE"""),0.0) -> 0 | L14: =IFERROR(__xludf.DUMMYFUNCTION("""COMPUTED_VALUE"""),-960.0) -> -960
B16: =IFERROR(__xludf.DUMMYFUNCTION("""COMPUTED_VALUE"""),"Returns") -> Returns | C16: =IFERROR(__xludf.DUMMYFUNCTION("""COMPUTED_VALUE"""),-2922.090000000002) -> -2922.09 | D16: =IFERROR(__xludf.DUMMYFUNCTION("""COMPUTED_VALUE"""),-71.64) -> -71.64 | E16: =IFERROR(__xludf.DUMMYFUNCTION("""COMPUTED_VALUE"""),-127.65) -> -127.65 | F16: =IFERROR(__xludf.DUMMYFUNCTION("""COMPUTED_VALUE"""),-26.01) -> -26.01 | G16: =IFERROR(__xludf.DUMMYFUNCTION("""COMPUTED_VALUE"""),0.0) -> 0
B17: =IFERROR(__xludf.DUMMYFUNCTION("""COMPUTED_VALUE"""),"Keystone") -> Keystone | C17: =IFERROR(__xludf.DUMMYFUNCTION("""COMPUTED_VALUE"""),-2835.680000000002) -> -2835.68 | D17: =IFERROR(__xludf.DUMMYFUNCTION("""COMPUTED_VALUE"""),-71.64) -> -71.64 | E17: =IFERROR(__xludf.DUMMYFUNCTION("""COMPUTED_VALUE"""),-127.65) -> -127.65 | F17: =IFERROR(__xludf.DUMMYFUNCTION("""COMPUTED_VALUE"""),-26.01) -> -26.01 | G17: =IFERROR(__xludf.DUMMYFUNCTION("""COMPUTED_VALUE"""),0.0) -> 0
B18: =IFERROR(__xludf.DUMMYFUNCTION("""COMPUTED_VALUE"""),"eBay") -> eBay | C18: =IFERROR(__xludf.DUMMYFUNCTION("""COMPUTED_VALUE"""),-16.67) -> -16.67 | D18: =IFERROR(__xludf.DUMMYFUNCTION("""COMPUTED_VALUE"""),0.0) -> 0 | E18: =IFERROR(__xludf.DUMMYFUNCTION("""COMPUTED_VALUE"""),0.0) -> 0 | F18: =IFERROR(__xludf.DUMMYFUNCTION("""COMPUTED_VALUE"""),0.0) -> 0 | G18: =IFERROR(__xludf.DUMMYFUNCTION("""COMPUTED_VALUE"""),0.0) -> 0
B19: =IFERROR(__xludf.DUMMYFUNCTION("""COMPUTED_VALUE"""),"TAAS") -> TAAS | C19: =IFERROR(__xludf.DUMMYFUNCTION("""COMPUTED_VALUE"""),-69.74) -> -69.74 | D19: =IFERROR(__xludf.DUMMYFUNCTION("""COMPUTED_VALUE"""),0.0) -> 0 | E19: =IFERROR(__xludf.DUMMYFUNCTION("""COMPUTED_VALUE"""),0.0) -> 0 | F19: =IFERROR(__xludf.DUMMYFUNCTION("""COMPUTED_VALUE"""),0.0) -> 0 | G19: =IFERROR(__xludf.DUMMYFUNCTION("""COMPUTED_VALUE"""),0.0) -> 0
B20: =IFERROR(__xludf.DUMMYFUNCTION("""COMPUTED_VALUE"""),"RR-Wally's") -> RR-Wally's | C20: =IFERROR(__xludf.DUMMYFUNCTION("""COMPUTED_VALUE"""),0.0) -> 0 | D20: =IFERROR(__xludf.DUMMYFUNCTION("""COMPUTED_VALUE"""),0.0) -> 0 | E20: =IFERROR(__xludf.DUMMYFUNCTION("""COMPUTED_VALUE"""),0.0) -> 0 | F20: =IFERROR(__xludf.DUMMYFUNCTION("""COMPUTED_VALUE"""),0.0) -> 0 | G20: =IFERROR(__xludf.DUMMYFUNCTION("""COMPUTED_VALUE"""),0.0) -> 0
