Workbook
Name Walmart: 'Year to Date Profitability Repo'!$1:$989

Sheet Year to Date Profitability Repo
B1: Walmart
B2: Net Margins | C2: =IFERROR(__xludf.DUMMYFUNCTION("importrange(""https://docs.google.com/spreadsheets/d/1SpIQ08zdW-3HpkzcmPmRLalvhgOSNVUg8BE8acIkxHI/edit?gid=0#gid=0"",""PeriodSynch"")"),"Year to Date") -> Year to Date | D2: =IFERROR(__xludf.DUMMYFUNCTION("""COMPUTED_VALUE"""),"Last Month") -> Last Month | E2: =IFERROR(__xludf.DUMMYFUNCTION("""COMPUTED_VALUE"""),"Month to Date") -> Month to Date | F2: =IFERROR(__xludf.DUMMYFUNCTION("""COMPUTED_VALUE"""),"This Week") -> This Week | G2: =IFERROR(__xludf.DUMMYFUNCTION("""COMPUTED_VALUE"""),"Last Week") -> Last Week
C3: =IFERROR(__xludf.DUMMYFUNCTION("""COMPUTED_VALUE"""),2025.0) -> 2025 | D3: =IFERROR(__xludf.DUMMYFUNCTION("""COMPUTED_VALUE"""),"November") -> November | E3: =IFERROR(__xludf.DUMMYFUNCTION("""COMPUTED_VALUE"""),"December") -> December | F3: =IFERROR(__xludf.DUMMYFUNCTION("""COMPUTED_VALUE"""),45999.0) -> 45999 | G3: =IFERROR(__xludf.DUMMYFUNCTION("""COMPUTED_VALUE"""),45992.0) -> 45992
B4: 20% Projection | C4: =C5*20% -> 1597.952 | D4: =D5*20% -> 236 | E4: =E5*20% -> 0 | F4: =F5*20% -> 0 | G4: =G5*20% -> 0
B5: Net Profit Walmart | C5: =C7+(C12+C18+C33) -> 7989.76 | D5: =D7+(D12+D18+D33) -> 1180 | E5: =E7+(E12+E18+E33) -> 0 | F5: =F7+(F12+F18+F33) -> 0 | G5: =G7+(G12+G18+G33) -> 0
B6: Item Profit Vs. Returned Items | C6: =C7+C12 -> 8530.01 | D6: =D7+D12 -> 1235.93 | E6: =E7+E12 -> 0 | F6: =F7+F12 -> 0 | G6: =G7+G12 -> 0
B7: Walmart Item Sales Profit | C7: =SUM(C8:C10) -> 12259.45 | D7: =SUM(D8:D10) -> 1613.47 | E7: =SUM(E8:E10) -> 0 | F7: =SUM(F8:F10) -> 0 | G7: =SUM(G8:G10) -> 0
B8: Keystone | C8: =sumifs('Statements Legacy Report '!$CB:$CB,'Statements Legacy Report '!$CE:$CE,C$3,'Statements Legacy Report '!$F:$F,"SALE",'Statements Legacy Report '!$BW:$BW,$B8) -> 12259.45 | D8: =sumifs('Statements Legacy Report '!$CB:$CB,'Statements Legacy Report '!$CF:$CF,D$3,'Statements Legacy Report '!$F:$F,"SALE",'Statements Legacy Report '!$BW:$BW,$B8) -> 1613.47 | E8: =sumifs('Statements Legacy Report '!$CB:$CB,'Statements Legacy Report '!$CF:$CF,E$3,'Statements Legacy Report '!$F:$F,"SALE",'Statements Legacy Report '!$BW:$BW,$B8) -> 0 | F8: =sumifs('Statements Legacy Report '!$CB:$CB,'Statements Legacy Report '!$CG:$CG,F$2,'Statements Legacy Report '!$F:$F,"SALE",'Statements Legacy Report '!$BW:$BW,$B8) -> 0 | G8: =sumifs('Statements Legacy Report '!$CB:$CB,'Statements Legacy Report '!$CG:$CG,G$2,'Statements Legacy Report '!$F:$F,"SALE",'Statements Legacy Report '!$BW:$BW,$B8) -> 0
B9: eBay | C9: =sumifs('Statements Legacy Report '!$CB:$CB,'Statements Legacy Report '!$CE:$CE,C$3,'Statements Legacy Report '!$F:$F,"SALE",'Statements Legacy Report '!$BW:$BW,$B9) -> 0 | D9: =sumifs('Statements Legacy Report '!$CB:$CB,'Statements Legacy Report '!$CF:$CF,D$3,'Statements Legacy Report '!$F:$F,"SALE",'Statements Legacy Report '!$BW:$BW,$B9) -> 0 | E9: =sumifs('Statements Legacy Report '!$CB:$CB,'Statements Legacy Report '!$CF:$CF,E$3,'Statements Legacy Report '!$F:$F,"SALE",'Statements Legacy Report '!$BW:$BW,$B9) -> 0 | F9: =sumifs('Statements Legacy Report '!$CB:$CB,'Statements Legacy Report '!$CG:$CG,F$2,'Statements Legacy Report '!$F:$F,"SALE",'Statements Legacy Report '!$BW:$BW,$B9) -> 0 | G9: =sumifs('Statements Legacy Report '!$CB:$CB,'Statements Legacy Report '!$CG:$CG,G$2,'Statements Legacy Report '!$F:$F,"SALE",'Statements Legacy Report '!$BW:$BW,$B9) -> 0
B10: TAAS | C10: =sumifs('Statements Legacy Report '!$CB:$CB,'Statements Legacy Report '!$CE:$CE,C$3,'Statements Legacy Report '!$F:$F,"SALE",'Statements Legacy Report '!$BW:$BW,$B10) -> 0 | D10: =sumifs('Statements Legacy Report '!$CB:$CB,'Statements Legacy Report '!$CF:$CF,D$3,'Statements Legacy Report '!$F:$F,"SALE",'Statements Legacy Report '!$BW:$BW,$B10) -> 0 | E10: =sumifs('Statements Legacy Report '!$CB:$CB,'Statements Legacy Report '!$CF:$CF,E$3,'Statements Legacy Report '!$F:$F,"SALE",'Statements Legacy Report '!$BW:$BW,$B10) -> 0 | F10: =sumifs('Statements Legacy Report '!$CB:$CB,'Statements Legacy Report '!$CG:$CG,F$2,'Statements Legacy Report '!$F:$F,"SALE",'Statements Legacy Report '!$BW:$BW,$B10) -> 0 | G10: =sumifs('Statements Legacy Report '!$CB:$CB,'Statements Legacy Report '!$CG:$CG,G$2,'Statements Legacy Report '!$F:$F,"SALE",'Statements Legacy Report '!$BW:$BW,$B10) -> 0
B12: Returns Items Cost | C12: =SUM(C13:C15) -> -3729.44 | D12: =SUM(D13:D15) -> -377.54 | E12: =SUM(E13:E15) -> 0 | F12: =SUM(F13:F15) -> 0 | G12: =SUM(G13:G15) -> 0
B13: Keystone | C13: =sumifs('Statements Legacy Report '!$CA:$CA,'Statements Legacy Report '!$F:$F,"REFUNDED",'Statements Legacy Report '!$BW:$BW,$B13,'Statements Legacy Report '!CE:CE,C$3)*-1 -> -3729.44 | D13: =sumifs('Statements Legacy Report '!$CA:$CA,'Statements Legacy Report '!$F:$F,"REFUNDED",'Statements Legacy Report '!$BW:$BW,$B13,'Statements Legacy Report '!$CF:$CF,D$3)*-1 -> -377.54 | E13: =sumifs('Statements Legacy Report '!$CA:$CA,'Statements Legacy Report '!$F:$F,"REFUNDED",'Statements Legacy Report '!$BW:$BW,$B13,'Statements Legacy Report '!$CF:$CF,E$3)*-1 -> 0 | F13: =sumifs('Statements Legacy Report '!$CA:$CA,'Statements Legacy Report '!$F:$F,"REFUNDED",'Statements Legacy Report '!$BW:$BW,$B13,'Statements Legacy Report '!$CG:$CG,F$2)*-1 -> 0 | G13: =sumifs('Statements Legacy Report '!$CA:$CA,'Statements Legacy Report '!$F:$F,"REFUNDED",'Statements Legacy Report '!$BW:$BW,$B13,'Statements Legacy Report '!$CG:$CG,G$2)*-1 -> 0
B14: eBay | C14: =sumifs('Statements Legacy Report '!$CA:$CA,'Statements Legacy Report '!$F:$F,"REFUNDED",'Statements Legacy Report '!$BW:$BW,$B14,'Statements Legacy Report '!CE:CE,C$3)*-1 -> 0 | D14: =sumifs('Statements Legacy Report '!$CA:$CA,'Statements Legacy Report '!$F:$F,"REFUNDED",'Statements Legacy Report '!$BW:$BW,$B14,'Statements Legacy Report '!$CF:$CF,D$3)*-1 -> 0 | E14: =sumifs('Statements Legacy Report '!$CA:$CA,'Statements Legacy Report '!$F:$F,"REFUNDED",'Statements Legacy Report '!$BW:$BW,$B14,'Statements Legacy Report '!$CF:$CF,E$3)*-1 -> 0 | F14: =sumifs('Statements Legacy Report '!$CA:$CA,'Statements Legacy Report '!$F:$F,"REFUNDED",'Statements Legacy Report '!$BW:$BW,$B14,'Statements Legacy Report '!$CG:$CG,F$2)*-1 -> 0 | G14: =sumifs('Statements Legacy Report '!$CA:$CA,'Statements Legacy Report '!$F:$F,"REFUNDED",'Statements Legacy Report '!$BW:$BW,$B14,'Statements Legacy Report '!$CG:$CG,G$2)*-1 -> 0
B15: TAAS | C15: =sumifs('Statements Legacy Report '!$CA:$CA,'Statements Legacy Report '!$F:$F,"REFUNDED",'Statements Legacy Report '!$BW:$BW,$B15,'Statements Legacy Report '!CE:CE,C$3)*-1 -> 0 | D15: =sumifs('Statements Legacy Report '!$CA:$CA,'Statements Legacy Report '!$F:$F,"REFUNDED",'Statements Legacy Report '!$BW:$BW,$B15,'Statements Legacy Report '!$CF:$CF,D$3)*-1 -> 0 | E15: =sumifs('Statements Legacy Report '!$CA:$CA,'Statements Legacy Report '!$F:$F,"REFUNDED",'Statements Legacy Report '!$BW:$BW,$B15,'Statements Legacy Report '!$CF:$CF,E$3)*-1 -> 0 | F15: =sumifs('Statements Legacy Report '!$CA:$CA,'Statements Legacy Report '!$F:$F,"REFUNDED",'Statements Legacy Report '!$BW:$BW,$B15,'Statements Legacy Report '!$CG:$CG,F$2)*-1 -> 0 | G15: =sumifs('Statements Legacy Report '!$CA:$CA,'Statements Legacy Report '!$F:$F,"REFUNDED",'Statements Legacy Report '!$BW:$BW,$B15,'Statements Legacy Report '!$CG:$CG,G$2)*-1 -> 0
B18: Other Fees | C18: =SUM(C19) -> -540.25 | D18: =SUM(D19) -> -55.93 | E18: =SUM(E19) -> 0 | F18: =SUM(F19) -> 0 | G18: =SUM(G19) -> 0
B19: Adjustment Charges | C19: =sumifs('Statements Legacy Report '!$V:$V,'Statements Legacy Report '!$F:$F,"ADJMNT",'Statements Legacy Report '!CE:CE,C3) -> -540.25 | D19: =sumifs('Statements Legacy Report '!$V:$V,'Statements Legacy Report '!$F:$F,"ADJMNT",'Statements Legacy Report '!CF:CF,D3) -> -55.93 | E19: =sumifs('Statements Legacy Report '!$V:$V,'Statements Legacy Report '!$F:$F,"ADJMNT",'Statements Legacy Report '!CF:CF,E3) -> 0 | F19: =sumifs('Statements Legacy Report '!$V:$V,'Statements Legacy Report '!$F:$F,"ADJMNT",'Statements Legacy Report '!CG:CG,F2) -> 0 | G19: =sumifs('Statements Legacy Report '!$V:$V,'Statements Legacy Report '!$F:$F,"ADJMNT",'Statements Legacy Report '!CG:CG,G2) -> 0
B21: Purchase Reconciliations
B22: Keystone | C22: =sumifs('Statements Legacy Report '!$CA:$CA,'Statements Legacy Report '!$CE:$CE,C$3,'Statements Legacy Report '!$F:$F,"SALE",'Statements Legacy Report '!$BW:$BW,$B22) -> 17711.51 | D22: =sumifs('Statements Legacy Report '!$CA:$CA,'Statements Legacy Report '!$CF:$CF,D$3,'Statements Legacy Report '!$F:$F,"SALE",'Statements Legacy Report '!$BW:$BW,$B22) -> 2265.59 | E22: =sumifs('Statements Legacy Report '!$CA:$CA,'Statements Legacy Report '!$CF:$CF,E$3,'Statements Legacy Report '!$F:$F,"SALE",'Statements Legacy Report '!$BW:$BW,$B22) -> 0 | F22: =sumifs('Statements Legacy Report '!$CA:$CA,'Statements Legacy Report '!$CG:$CG,F$2,'Statements Legacy Report '!$F:$F,"SALE",'Statements Legacy Report '!$BW:$BW,$B22) -> 0 | G22: =sumifs('Statements Legacy Report '!$CA:$CA,'Statements Legacy Report '!$CG:$CG,G$2,'Statements Legacy Report '!$F:$F,"SALE",'Statements Legacy Report '!$BW:$BW,$B22) -> 0
B23: TAAS | C23: =sumifs('Statements Legacy Report '!$CA:$CA,'Statements Legacy Report '!$CE:$CE,C$3,'Statements Legacy Report '!$F:$F,"SALE",'Statements Legacy Report '!$BW:$BW,$B23) -> 0 | D23: =sumifs('Statements Legacy Report '!$CA:$CA,'Statements Legacy Report '!$CF:$CF,D$3,'Statements Legacy Report '!$F:$F,"SALE",'Statements Legacy Report '!$BW:$BW,$B23) -> 0 | E23: =sumifs('Statements Legacy Report '!$CA:$CA,'Statements Legacy Report '!$CF:$CF,E$3,'Statements Legacy Report '!$F:$F,"SALE",'Statements Legacy Report '!$BW:$BW,$B23) -> 0 | F23: =sumifs('Statements Legacy Report '!$CA:$CA,'Statements Legacy Report '!$CG:$CG,F$2,'Statements Legacy Report '!$F:$F,"SALE",'Statements Legacy Report '!$BW:$BW,$B23) -> 0 | G23: =sumifs('Statements Legacy Report '!$CA:$CA,'Statements Legacy Report '!$CG:$CG,G$2,'Statements Legacy Report '!$F:$F,"SALE",'Statements Legacy Report '!$BW:$BW,$B23) -> 0
B24: eBay | C24: =sumifs('Statements Legacy Report '!$CA:$CA,'Statements Legacy Report '!$CE:$CE,C$3,'Statements Legacy Report '!$F:$F,"SALE",'Statements Legacy Report '!$BW:$BW,$B24) -> 0 | D24: =sumifs('Statements Legacy Report '!$CA:$CA,'Statements Legacy Report '!$CF:$CF,D$3,'Statements Legacy Report '!$F:$F,"SALE",'Statements Legacy Report '!$BW:$BW,$B24) -> 0 | E24: =sumifs('Statements Legacy Report '!$CA:$CA,'Statements Legacy Report '!$CF:$CF,E$3,'Statements Legacy Report '!$F:$F,"SALE",'Statements Legacy Report '!$BW:$BW,$B24) -> 0 | F24: =sumifs('Statements Legacy Report '!$CA:$CA,'Statements Legacy Report '!$CG:$CG,F$2,'Statements Legacy Report '!$F:$F,"SALE",'Statements Legacy Report '!$BW:$BW,$B24) -> 0 | G24: =sumifs('Statements Legacy Report '!$CA:$CA,'Statements Legacy Report '!$CG:$CG,G$2,'Statements Legacy Report '!$F:$F,"SALE",'Statements Legacy Report '!$BW:$BW,$B24) -> 0
B26: Sales | C26: =IFERROR(__xludf.DUMMYFUNCTION("importrange(""https://docs.google.com/spreadsheets/d/1SpIQ08zdW-3HpkzcmPmRLalvhgOSNVUg8BE8acIkxHI/edit?gid=0#gid=0"",""PeriodSynch"")"),"Year to Date") -> Year to Date | D26: =IFERROR(__xludf.DUMMYFUNCTION("""COMPUTED_VALUE"""),"Last Month") -> Last Month | E26: =IFERROR(__xludf.DUMMYFUNCTION("""COMPUTED_VALUE"""),"Month to Date") -> Month to Date | F26: =IFERROR(__xludf.DUMMYFUNCTION("""COMPUTED_VALUE"""),"This Week") -> This Week | G26: =IFERROR(__xludf.DUMMYFUNCTION("""COMPUTED_VALUE"""),"Last Week") -> Last Week
C27: =IFERROR(__xludf.DUMMYFUNCTION("""COMPUTED_VALUE"""),2025.0) -> 2025 | D27: =IFERROR(__xludf.DUMMYFUNCTION("""COMPUTED_VALUE"""),"November") -> November | E27: =IFERROR(__xludf.DUMMYFUNCTION("""COMPUTED_VALUE"""),"December") -> December | F27: =IFERROR(__xludf.DUMMYFUNCTION("""COMPUTED_VALUE"""),45999.0) -> 45999 | G27: =IFERROR(__xludf.DUMMYFUNCTION("""COMPUTED_VALUE"""),45992.0) -> 45992
B28: All Vendors | C28: =SUM(C29:C31) -> 33274 | D28: =SUM(D29:D31) -> 4244.8 | E28: =SUM(E29:E31) -> 0 | F28: =SUM(F29:F31) -> 0 | G28: =SUM(G29:G31) -> 0
B29: Keystone | C29: =sumifs('Statements Legacy Report '!$U:$U,'Statements Legacy Report '!$CE:$CE,C$3,'Statements Legacy Report '!$F:$F,"SALE",'Statements Legacy Report '!$BW:$BW,$B29) -> 33274 | D29: =sumifs('Statements Legacy Report '!$U:$U,'Statements Legacy Report '!$CF:$CF,D$3,'Statements Legacy Report '!$F:$F,"SALE",'Statements Legacy Report '!$BW:$BW,$B29) -> 4244.8 | E29: =sumifs('Statements Legacy Report '!$U:$U,'Statements Legacy Report '!$CF:$CF,E$3,'Statements Legacy Report '!$F:$F,"SALE",'Statements Legacy Report '!$BW:$BW,$B29) -> 0 | F29: =sumifs('Statements Legacy Report '!$U:$U,'Statements Legacy Report '!$CG:$CG,F$2,'Statements Legacy Report '!$F:$F,"SALE",'Statements Legacy Report '!$BW:$BW,$B29) -> 0 | G29: =sumifs('Statements Legacy Report '!$U:$U,'Statements Legacy Report '!$CG:$CG,G$2,'Statements Legacy Report '!$F:$F,"SALE",'Statements Legacy Report '!$BW:$BW,$B29) -> 0
B30: eBay | C30: =sumifs('Statements Legacy Report '!$U:$U,'Statements Legacy Report '!$CE:$CE,C$3,'Statements Legacy Report '!$F:$F,"SALE",'Statements Legacy Report '!$BW:$BW,$B30) -> 0 | D30: =sumifs('Statements Legacy Report '!$U:$U,'Statements Legacy Report '!$CF:$CF,D$3,'Statements Legacy Report '!$F:$F,"SALE",'Statements Legacy Report '!$BW:$BW,$B30) -> 0 | E30: =sumifs('Statements Legacy Report '!$U:$U,'Statements Legacy Report '!$CF:$CF,E$3,'Statements Legacy Report '!$F:$F,"SALE",'Statements Legacy Report '!$BW:$BW,$B30) -> 0 | F30: =sumifs('Statements Legacy Report '!$U:$U,'Statements Legacy Report '!$CG:$CG,F$2,'Statements Legacy Report '!$F:$F,"SALE",'Statements Legacy Report '!$BW:$BW,$B30) -> 0 | G30: =sumifs('Statements Legacy Report '!$U:$U,'Statements Legacy Report '!$CG:$CG,G$2,'Statements Legacy Report '!$F:$F,"SALE",'Statements Legacy Report '!$BW:$BW,$B30) -> 0
B31: TAAS | C31: =sumifs('Statements Legacy Report '!$U:$U,'Statements Legacy Report '!$CE:$CE,C$3,'Statements Legacy Report '!$F:$F,"SALE",'Statements Legacy Report '!$BW:$BW,$B31) -> 0 | D31: =sumifs('Statements Legacy Report '!$U:$U,'Statements Legacy Report '!$CF:$CF,D$3,'Statements Legacy Report '!$F:$F,"SALE",'Statements Legacy Report '!$BW:$BW,$B31) -> 0 | E31: =sumifs('Statements Legacy Report '!$U:$U,'Statements Legacy Report '!$CF:$CF,E$3,'Statements Legacy Report '!$F:$F,"SALE",'Statements Legacy Report '!$BW:$BW,$B31) -> 0 | F31: =sumifs('Statements Legacy Report '!$U:$U,'Statements Legacy Report '!$CG:$CG,F$2,'Statements Legacy Report '!$F:$F,"SALE",'Statements Legacy Report '!$BW:$BW,$B31) -> 0 | G31: =sumifs('Statements Legacy Report '!$U:$U,'Statements Legacy Report '!$CG:$CG,G$2,'Statements Legacy Report '!$F:$F,"SALE",'Statements Legacy Report '!$BW:$BW,$B31) -> 0
B33: Ads and Campaigns

Sheet Statements Legacy Report 
A1: Walmart.com Order # | B1: Walmart.com Order Line # | C1: Walmart.com PO # | D1: Walmart.com P.O. Line # | E1: Partner Order # | F1: Transaction Type | G1: Transaction Date Time | H1: Shipped Qty | I1: Partner Item ID | J1: Partner GTIN | K1: Partner Item name | L1: Product tax code | M1: Shipping tax code | N1: Gift wrap tax code | O1: Ship to state | P1: Ship to county | Q1: County Code | R1: Ship to city | S1: Zip code | T1: shipping_method | U1: Total tender to / from customer | V1: Payable to Partner from Sale | W1: Commission from Sale | X1: Commission Rate | Y1: Gross Sales Revenue | Z1: Refunded Retail Sales | AA1: Sales refund for Escalation | AB1: Gross Shipping Revenue | AC1: Gross Shipping Refunded | AD1: Shipping refund for Escalation | AE1: Net Shipping Revenue | AF1: Gross Fee Revenue | AG1: Gross Fee Refunded | AH1: Fee refund for Escalation | AI1: Net Fee Revenue | AJ1: Gift Wrap Quantity | AK1: Gross Gift-Wrap Revenue | AL1: Gross Gift-Wrap Refunded | AM1: Gift wrap refund for Escalation | AN1: Net Gift Wrap Revenue | AO1: Tax on Sales Revenue | AP1: Tax on Shipping Revenue | AQ1: Tax on Gift-Wrap Revenue | AR1: Tax on Fee Revenue | AS1: Effective tax rate | AT1: Tax on Refunded Sales | AU1: Tax on Shipping Refund | AV1: Tax on Gift-Wrap Refund | AW1: Tax on Fee Refund | AX1: Tax on Sales refund for Escalation | AY1: Tax on Shipping Refund for Escalation | AZ1: Tax on Gift-Wrap Refund for escalation | BA1: Tax on Fee Refund for escalation | BB1: Total NET Tax Collected | BC1: Tax Withheld | BD1: Adjustment Description | BE1: Adjustment Code | BF1: Original Item price | BG1: Original Commission Amount | BH1: Spec Category | BI1: Contract Category | BJ1: Product Type | BK1: Flex Commission Rule | BL1: Return Reason Code | BM1: Return Reason Description | BN1: Fee Withheld Flag | BO1: Fulfillment Type | BP1: Fulfillment Details | BQ1: Commission Incentive Program | BR1: Commission Saving | BS1: Customer Promo Type | BT1: Total Walmart Funded Savings | BU1: Total Walmart Funded Savings Program | BV1: Item Condition | BW1: Vendor | BX1: Fill PN | BY1: Item Cost | BZ1: Ship Cost | CA1: Total Cost | CB1: Net Profit | CC1: Returned Item | CD1: Returned Item Vendor | CE1: Year | CF1: Month | CG1: ='Year to Date Profitability Repo'!F3 -> 45999
A2: 200013453756657 | B2: 1 | C2: 109015177922183 | D2: 1 | F2: SALE | G2: 45807 | H2: 1 | I2: WM-FR-IMP-4261104150-16CH6VP | J2: 460776237725 | K2: 16 Chrome Wheel Skins Set Compatible with 16-23 Toyota Tacoma TRD Off-Road TRD Sport SR SR5 Limited 17-23 Tacoma TRD Pro 2021 Tacoma Trail & 2023 Tacoma Trail Special Edition | L2: 2038710 | O2: FL | R2: Miami | S2: 33177 | T2: Marketplace standard | U2: 115.54 | V2: 100.42 | W2: 7.56 | X2: 7 | Y2: 107.98 | Z2: 0 | AA2: 0 | AB2: 0 | AC2: 0 | AD2: 0 | AE2: 0 | AF2: 0 | AG2: 0 | AH2: 0 | AI2: 0 | AJ2: 0 | AK2: 0 | AL2: 0 | AM2: 0 | AN2: 0 | AO2: 7.56 | AP2: 0 | AQ2: 0 | AR2: 0 | AS2: 0 | AT2: 0 | AU2: 0 | AV2: 0 | AW2: 0 | AX2: 0 | AY2: 0 | AZ2: 0 | BA2: 0 | BB2: 7.56 | BC2: Y | BG2: -10.8 | BH2: Wheels & Wheel Components | BI2: Tires & Wheels | BJ2: Automotive Wheel Covers & Hub Caps | BK2: PRO-119076-18.0 | BN2: N | BO2: Seller Fulfilled | BP2: Delivery | BQ2: New Seller Saving | BR2: 3.24 | BW2: =if(OR(F2="SALE",F2="REFUNDED"),IFERROR(Vlookup(I2,'Listing SKU - Fill SKU Mapping'!A:C,3,false),"Map"),"") -> Keystone | BX2: =IF(OR(F2="SALE",F2="REFUNDED")=TRUE,iferror(Vlookup(I2,'Listing SKU - Fill SKU Mapping'!A:B,2,false),"Map"),"") -> IMP445X | BY2: =IF(OR(F2="SALE",F2="REFUNDED")=TRUE,iferror(Vlookup(I2,'Listing SKU - Fill SKU Mapping'!A:D,4,false),"Map"),"") -> 49.71 | BZ2: =If(BW2="Keystone",11.5,"") -> 11.5 | CA2: =IF(ISNUMBER(BY2)=TRUE,BY2+BZ2,"") -> 61.21 | CB2: =if(F2="SALE",V2-CA2,"") -> 39.21 | CC2: =if(F2="REFUNDED",iferror(Vlookup(I2,'Listing SKU - Fill SKU Mapping'!A:B,2,false),"Map"),"") | CD2: =if(F2="REFUNDED",iferror(Vlookup(I2,'Listing SKU - Fill SKU Mapping'!A:C,3,false),"Map"),"") | CE2: =TEXT(G2,"YYYY") -> 2025 | CF2: =TEXT(G2,"MMMM") -> May | CG2: =IF(AND((G2-CG$1)>=0,(G2-CG$1)<=6), "This Week",IF(AND((G2-CG$1)>=-7,(G2-CG$1)<=-1), "Last Week",""))
A3: 200013452446032 | B3: 1 | C3: 109014451419163 | D3: 1 | F3: SALE | G3: 45804 | H3: 1 | I3: WM-FR-IMP-6BG71GSAAB-17CH10S | J3: 465595333719 | K3: Set of 4 17 inch Chrome ABS Wheel Skins Compatible with 2019 - 2021 Jeep Cherokee Latitude; 2019 - 2021 Jeep Cherokee Latitude Plus Impostors for 6BG71GSAAB Wheel Series | L3: 2038710 | O3: MD | R3: Essex | S3: 21221 | T3: Marketplace standard | U3: 93.26 | V3: 81.82 | W3: 6.16 | X3: 7 | Y3: 87.98 | Z3: 0 | AA3: 0 | AB3: 0 | AC3: 0 | AD3: 0 | AE3: 0 | AF3: 0 | AG3: 0 | AH3: 0 | AI3: 0 | AJ3: 0 | AK3: 0 | AL3: 0 | AM3: 0 | AN3: 0 | AO3: 5.28 | AP3: 0 | AQ3: 0 | AR3: 0 | AS3: 0 | AT3: 0 | AU3: 0 | AV3: 0 | AW3: 0 | AX3: 0 | AY3: 0 | AZ3: 0 | BA3: 0 | BB3: 5.28 | BC3: Y | BG3: -8.8 | BH3: Wheels & Wheel Components | BI3: Tires & Wheels | BJ3: Automotive Wheel Covers & Hub Caps | BK3: PRO-119076-17.0 | BN3: N | BO3: Seller Fulfilled | BP3: Delivery | BQ3: New Seller Saving | BR3: 2.64 | BW3: =if(OR(F3="SALE",F3="REFUNDED"),IFERROR(Vlookup(I3,'Listing SKU - Fill SKU Mapping'!A:C,3,false),"Map"),"") -> Keystone | BX3: =IF(OR(F3="SALE",F3="REFUNDED")=TRUE,iferror(Vlookup(I3,'Listing SKU - Fill SKU Mapping'!A:B,2,false),"Map"),"") -> IMP457X | BY3: =IF(OR(F3="SALE",F3="REFUNDED")=TRUE,iferror(Vlookup(I3,'Listing SKU - Fill SKU Mapping'!A:D,4,false),"Map"),"") -> 49.71 | BZ3: =If(BW3="Keystone",11.5,"") -> 11.5 | CA3: =IF(ISNUMBER(BY3)=TRUE,BY3+BZ3,"") -> 61.21 | CB3: =if(F3="SALE",V3-CA3,"") -> 20.61 | CC3: =if(F3="REFUNDED",iferror(Vlookup(I3,'Listing SKU - Fill SKU Mapping'!A:B,2,false),"Map"),"") | CD3: =if(F3="REFUNDED",iferror(Vlookup(I3,'Listing SKU - Fill SKU Mapping'!A:C,3,false),"Map"),"") | CE3: =TEXT(G3,"YYYY") -> 2025 | CF3: =TEXT(G3,"MMMM") -> May | CG3: =IF(AND((G3-CG$1)>=0,(G3-CG$1)<=6), "This Week",IF(AND((G3-CG$1)>=-7,(G3-CG$1)<=-1), "Last Week",""))
A4: 200013446882232 | B4: 1 | C4: 109014970676989 | D4: 1 | F4: SALE | G4: 45805 | H4: 1 | I4: WM-KS-FRHC-53094-17SL | J4: 467129945498 | K4: Fuel Rider Set of 4 17 inch Silver Snap-On Hubcaps With 10 Spoke Compatible With 2014-2020 Nissan Rogue S Standard Steel Wheel Covers | L4: 2038710 | O4: TN | R4: Dresden | S4: 38225 | T4: Marketplace standard | U4: 73.51 | V4: 62.29 | W4: 4.69 | X4: 7 | Y4: 66.98 | Z4: 0 | AA4: 0 | AB4: 0 | AC4: 0 | AD4: 0 | AE4: 0 | AF4: 0 | AG4: 0 | AH4: 0 | AI4: 0 | AJ4: 0 | AK4: 0 | AL4: 0 | AM4: 0 | AN4: 0 | AO4: 6.53 | AP4: 0 | AQ4: 0 | AR4: 0 | AS4: 0 | AT4: 0 | AU4: 0 | AV4: 0 | AW4: 0 | AX4: 0 | AY4: 0 | AZ4: 0 | BA4: 0 | BB4: 6.53 | BC4: Y | BG4: -6.7 | BH4: Wheels & Wheel Components | BI4: Tires & Wheels | BJ4: Automotive Wheel Covers & Hub Caps | BK4: PRO-119076-17.0 | BN4: N | BO4: Seller Fulfilled | BP4: Delivery | BQ4: New Seller Saving | BR4: 2.01 | BW4: =if(OR(F4="SALE",F4="REFUNDED"),IFERROR(Vlookup(I4,'Listing SKU - Fill SKU Mapping'!A:C,3,false),"Map"),"") -> Keystone | BX4: =IF(OR(F4="SALE",F4="REFUNDED")=TRUE,iferror(Vlookup(I4,'Listing SKU - Fill SKU Mapping'!A:B,2,false),"Map"),"") -> 51917S | BY4: =IF(OR(F4="SALE",F4="REFUNDED")=TRUE,iferror(Vlookup(I4,'Listing SKU - Fill SKU Mapping'!A:D,4,false),"Map"),"") -> 27.22 | BZ4: =If(BW4="Keystone",11.5,"") -> 11.5 | CA4: =IF(ISNUMBER(BY4)=TRUE,BY4+BZ4,"") -> 38.72 | CB4: =if(F4="SALE",V4-CA4,"") -> 23.57 | CC4: =if(F4="REFUNDED",iferror(Vlookup(I4,'Listing SKU - Fill SKU Mapping'!A:B,2,false),"Map"),"") | CD4: =if(F4="REFUNDED",iferror(Vlookup(I4,'Listing SKU - Fill SKU Mapping'!A:C,3,false),"Map"),"") | CE4: =TEXT(G4,"YYYY") -> 2025 | CF4: =TEXT(G4,"MMMM") -> May | CG4: =IF(AND((G4-CG$1)>=0,(G4-CG$1)<=6), "This Week",IF(AND((G4-CG$1)>=-7,(G4-CG$1)<=-1), "Last Week",""))
A5: 200013323467099 | B5: 1 | C5: 109014553225598 | D5: 1 | F5: SALE | G5: 45804 | H5: 1 | I5: WM-FR-IMP-9965087590-19GB5SS | J5: 465595354127 | K5: Set of 4 19 inch Gloss Black ABS Wheel Skins Compatible with 2014 - 2017 Mazda 6 Touring Impostors for 9965087590 Wheel Series | L5: 2038710 | O5: NC | R5: Fayetteville | S5: 28314 | T5: Marketplace standard | U5: 72.74 | V5: 63.22 | W5: 4.76 | X5: 7 | Y5: 67.98 | Z5: 0 | AA5: 0 | AB5: 0 | AC5: 0 | AD5: 0 | AE5: 0 | AF5: 0 | AG5: 0 | AH5: 0 | AI5: 0 | AJ5: 0 | AK5: 0 | AL5: 0 | AM5: 0 | AN5: 0 | AO5: 4.76 | AP5: 0 | AQ5: 0 | AR5: 0 | AS5: 0 | AT5: 0 | AU5: 0 | AV5: 0 | AW5: 0 | AX5: 0 | AY5: 0 | AZ5: 0 | BA5: 0 | BB5: 4.76 | BC5: Y | BG5: -6.8 | BH5: Wheels & Wheel Components | BI5: Tires & Wheels | BJ5: Automotive Wheel Covers & Hub Caps | BK5: PRO-119076-17.0 | BN5: N | BO5: Seller Fulfilled | BP5: Delivery | BQ5: New Seller Saving | BR5: 2.04 | BW5: =if(OR(F5="SALE",F5="REFUNDED"),IFERROR(Vlookup(I5,'Listing SKU - Fill SKU Mapping'!A:C,3,false),"Map"),"") -> Keystone | BX5: =IF(OR(F5="SALE",F5="REFUNDED")=TRUE,iferror(Vlookup(I5,'Listing SKU - Fill SKU Mapping'!A:B,2,false),"Map"),"") -> IMP472BLK | BY5: =IF(OR(F5="SALE",F5="REFUNDED")=TRUE,iferror(Vlookup(I5,'Listing SKU - Fill SKU Mapping'!A:D,4,false),"Map"),"") -> 48.52 | BZ5: =If(BW5="Keystone",11.5,"") -> 11.5 | CA5: =IF(ISNUMBER(BY5)=TRUE,BY5+BZ5,"") -> 60.02 | CB5: =if(F5="SALE",V5-CA5,"") -> 3.2 | CC5: =if(F5="REFUNDED",iferror(Vlookup(I5,'Listing SKU - Fill SKU Mapping'!A:B,2,false),"Map"),"") | CD5: =if(F5="REFUNDED",iferror(Vlookup(I5,'Listing SKU - Fill SKU Mapping'!A:C,3,false),"Map"),"") | CE5: =TEXT(G5,"YYYY") -> 2025 | CF5: =TEXT(G5,"MMMM") -> May | CG5: =IF(AND((G5-CG$1)>=0,(G5-CG$1)<=6), "This Week",IF(AND((G5-CG$1)>=-7,(G5-CG$1)<=-1), "Last Week",""))
A6: 200013323467099 | B6: 1 | C6: 109014553225598 | D6: 1 | F6: REFUNDED | G6: 45804 | H6: 1 | I6: WM-FR-IMP-9965087590-19GB5SS | J6: 465595354127 | K6: Set of 4 19 inch Gloss Black ABS Wheel Skins Compatible with 2014 - 2017 Mazda 6 Touring Impostors for 9965087590 Wheel Series | L6: 2038710 | R6: Fayetteville | S6: 28314 | U6: -72.74 | V6: -63.22 | W6: -4.76 | X6: 0 | Y6: 0 | Z6: -67.98 | AA6: 0 | AB6: 0 | AC6: 0 | AD6: 0 | AE6: 0 | AF6: 0 | AG6: 0 | AH6: 0 | AI6: 0 | AJ6: 0 | AK6: 0 | AL6: 0 | AM6: 0 | AN6: 0 | AO6: 0 | AP6: 0 | AQ6: 0 | AR6: 0 | AS6: 0 | AT6: -4.76 | AU6: 0 | AV6: 0 | AW6: 0 | AX6: 0 | AY6: 0 | AZ6: 0 | BA6: 0 | BB6: -4.76 | BC6: Y | BD6: Seller Initiated Returns | BE6: 5009 | BH6: Wheels & Wheel Components | BI6: Tires & Wheels | BL6: 1000 | BM6: No Longer Wanted | BN6: N | BO6: Seller Fulfilled | BW6: =if(OR(F6="SALE",F6="REFUNDED"),IFERROR(Vlookup(I6,'Listing SKU - Fill SKU Mapping'!A:C,3,false),"Map"),"") -> Keystone | BX6: =IF(OR(F6="SALE",F6="REFUNDED")=TRUE,iferror(Vlookup(I6,'Listing SKU - Fill SKU Mapping'!A:B,2,false),"Map"),"") -> IMP472BLK | BY6: =IF(OR(F6="SALE",F6="REFUNDED")=TRUE,iferror(Vlookup(I6,'Listing SKU - Fill SKU Mapping'!A:D,4,false),"Map"),"") -> 48.52 | BZ6: =If(BW6="Keystone",11.5,"") -> 11.5 | CA6: =IF(ISNUMBER(BY6)=TRUE,BY6+BZ6,"") -> 60.02 | CB6: =if(F6="SALE",V6-CA6,"") | CC6: =if(F6="REFUNDED",iferror(Vlookup(I6,'Listing SKU - Fill SKU Mapping'!A:B,2,false),"Map"),"") -> IMP472BLK | CD6: =if(F6="REFUNDED",iferror(Vlookup(I6,'Listing SKU - Fill SKU Mapping'!A:C,3,false),"Map"),"") -> Keystone | CE6: =TEXT(G6,"YYYY") -> 2025 | CF6: =TEXT(G6,"MMMM") -> May | CG6: =IF(AND((G6-CG$1)>=0,(G6-CG$1)<=6), "This Week",IF(AND((G6-CG$1)>=-7,(G6-CG$1)<=-1), "Last Week",""))
A7: 200013260994642 | B7: 1 | C7: 109015075316005 | D7: 1 | F7: SALE | G7: 45806 | H7: 1 | I7: WM-KS-FRHC-53073-15SL | J7: 469971001575 | K7: Fuel Rider Set of 4 15 inch Silver Snap-On Hubcaps With 6 Spoke Compatible With 2007-2012 Nissan Sentra Standard Steel Wheel Covers | L7: 2038710 | O7: MA | R7: Chicopee | S7: 1020 | T7: Marketplace standard | U7: 50.98 | V7: 44.62 | W7: 3.36 | X7: 7 | Y7: 47.98 | Z7: 0 | AA7: 0 | AB7: 0 | AC7: 0 | AD7: 0 | AE7: 0 | AF7: 0 | AG7: 0 | AH7: 0 | AI7: 0 | AJ7: 0 | AK7: 0 | AL7: 0 | AM7: 0 | AN7: 0 | AO7: 3 | AP7: 0 | AQ7: 0 | AR7: 0 | AS7: 0 | AT7: 0 | AU7: 0 | AV7: 0 | AW7: 0 | AX7: 0 | AY7: 0 | AZ7: 0 | BA7: 0 | BB7: 3 | BC7: Y | BG7: -4.8 | BH7: Wheels & Wheel Components | BI7: Tires & Wheels | BJ7: Automotive Wheel Covers & Hub Caps | BK7: PRO-119076-17.0 | BN7: N | BO7: Seller Fulfilled | BP7: Delivery | BQ7: New Seller Saving | BR7: 1.44 | BW7: =if(OR(F7="SALE",F7="REFUNDED"),IFERROR(Vlookup(I7,'Listing SKU - Fill SKU Mapping'!A:C,3,false),"Map"),"") -> Keystone | BX7: =IF(OR(F7="SALE",F7="REFUNDED")=TRUE,iferror(Vlookup(I7,'Listing SKU - Fill SKU Mapping'!A:B,2,false),"Map"),"") -> 43615S | BY7: =IF(OR(F7="SALE",F7="REFUNDED")=TRUE,iferror(Vlookup(I7,'Listing SKU - Fill SKU Mapping'!A:D,4,false),"Map"),"") -> 14.99 | BZ7: =If(BW7="Keystone",11.5,"") -> 11.5 | CA7: =IF(ISNUMBER(BY7)=TRUE,BY7+BZ7,"") -> 26.49 | CB7: =if(F7="SALE",V7-CA7,"") -> 18.13 | CC7: =if(F7="REFUNDED",iferror(Vlookup(I7,'Listing SKU - Fill SKU Mapping'!A:B,2,false),"Map"),"") | CD7: =if(F7="REFUNDED",iferror(Vlookup(I7,'Listing SKU - Fill SKU Mapping'!A:C,3,false),"Map"),"") | CE7: =TEXT(G7,"YYYY") -> 2025 | CF7: =TEXT(G7,"MMMM") -> May | CG7: =IF(AND((G7-CG$1)>=0,(G7-CG$1)<=6), "This Week",IF(AND((G7-CG$1)>=-7,(G7-CG$1)<=-1), "Last Week",""))
A8: 200013238424317 | B8: 1 | C8: 109015074290606 | D8: 1 | F8: SALE | G8: 45806 | H8: 1 | I8: WM-FR-IMP-3943-17CH5SP | J8: 460776238333 | K8: 17 inch Chrome ABS Wheel Skins Set Compatible with 2013-2016 Ford Escape 2017-2019 Escape SE & Impostors for 3943 Wheel Series | L8: 2038710 | O8: OH | R8: Amherst | S8: 44001 | T8: Marketplace standard | U8: 105.41 | V8: 92.05 | W8: 6.93 | X8: 7 | Y8: 98.98 | Z8: 0 | AA8: 0 | AB8: 0 | AC8: 0 | AD8: 0 | AE8: 0 | AF8: 0 | AG8: 0 | AH8: 0 | AI8: 0 | AJ8: 0 | AK8: 0 | AL8: 0 | AM8: 0 | AN8: 0 | AO8: 6.43 | AP8: 0 | AQ8: 0 | AR8: 0 | AS8: 0 | AT8: 0 | AU8: 0 | AV8: 0 | AW8: 0 | AX8: 0 | AY8: 0 | AZ8: 0 | BA8: 0 | BB8: 6.43 | BC8: Y | BG8: -9.9 | BH8: Wheels & Wheel Components | BI8: Tires & Wheels | BJ8: Automotive Wheel Covers & Hub Caps | BK8: PRO-119076-17.0 | BN8: N | BO8: Seller Fulfilled | BP8: Delivery | BQ8: New Seller Saving | BR8: 2.97 | BW8: =if(OR(F8="SALE",F8="REFUNDED"),IFERROR(Vlookup(I8,'Listing SKU - Fill SKU Mapping'!A:C,3,false),"Map"),"") -> Keystone | BX8: =IF(OR(F8="SALE",F8="REFUNDED")=TRUE,iferror(Vlookup(I8,'Listing SKU - Fill SKU Mapping'!A:B,2,false),"Map"),"") -> IMP371X | BY8: =IF(OR(F8="SALE",F8="REFUNDED")=TRUE,iferror(Vlookup(I8,'Listing SKU - Fill SKU Mapping'!A:D,4,false),"Map"),"") -> 43.79 | BZ8: =If(BW8="Keystone",11.5,"") -> 11.5 | CA8: =IF(ISNUMBER(BY8)=TRUE,BY8+BZ8,"") -> 55.29 | CB8: =if(F8="SALE",V8-CA8,"") -> 36.76 | CC8: =if(F8="REFUNDED",iferror(Vlookup(I8,'Listing SKU - Fill SKU Mapping'!A:B,2,false),"Map"),"") | CD8: =if(F8="REFUNDED",iferror(Vlookup(I8,'Listing SKU - Fill SKU Mapping'!A:C,3,false),"Map"),"") | CE8: =TEXT(G8,"YYYY") -> 2025 | CF8: =TEXT(G8,"MMMM") -> May | CG8: =IF(AND((G8-CG$1)>=0,(G8-CG$1)<=6), "This Week",IF(AND((G8-CG$1)>=-7,(G8-CG$1)<=-1), "Last Week",""))
A9: 200013169413632 | B9: 1 | C9: 109014759518921 | D9: 1 | F9: REFUNDED | G9: 45805 | H9: 1 | I9: WM-FR-IMP-84760166-18GB6VS | J9: 465595320771 | K9: Set of 4 18 inch Gloss Black ABS Wheel Skins Compatible with 2017 - 2019 GMC Acadia SLE; 2017 - 2019 GMC Acadia SLT Impostors for 84760166 22996315 Wheel Series | L9: 2038710 | R9: New Orleans | S9: 70125 | U9: -71.92 | V9: -61.36 | W9: -4.62 | X9: 0 | Y9: 0 | Z9: -65.98 | AA9: 0 | AB9: 0 | AC9: 0 | AD9: 0 | AE9: 0 | AF9: 0 | AG9: 0 | AH9: 0 | AI9: 0 | AJ9: 0 | AK9: 0 | AL9: 0 | AM9: 0 | AN9: 0 | AO9: 0 | AP9: 0 | AQ9: 0 | AR9: 0 | AS9: 0 | AT9: -5.94 | AU9: 0 | AV9: 0 | AW9: 0 | AX9: 0 | AY9: 0 | AZ9: 0 | BA9: 0 | BB9: -5.94 | BC9: Y | BD9: Seller Initiated Returns | BE9: 5009 | BH9: Wheels & Wheel Components | BI9: Tires & Wheels | BL9: 1000 | BM9: No Longer Wanted | BN9: N | BO9: Seller Fulfilled | BW9: =if(OR(F9="SALE",F9="REFUNDED"),IFERROR(Vlookup(I9,'Listing SKU - Fill SKU Mapping'!A:C,3,false),"Map"),"") -> Keystone | BX9: =IF(OR(F9="SALE",F9="REFUNDED")=TRUE,iferror(Vlookup(I9,'Listing SKU - Fill SKU Mapping'!A:B,2,false),"Map"),"") -> IMP466BLK | BY9: =IF(OR(F9="SALE",F9="REFUNDED")=TRUE,iferror(Vlookup(I9,'Listing SKU - Fill SKU Mapping'!A:D,4,false),"Map"),"") -> 62.33 | BZ9: =If(BW9="Keystone",11.5,"") -> 11.5 | CA9: =IF(ISNUMBER(BY9)=TRUE,BY9+BZ9,"") -> 73.83 | CB9: =if(F9="SALE",V9-CA9,"") | CC9: =if(F9="REFUNDED",iferror(Vlookup(I9,'Listing SKU - Fill SKU Mapping'!A:B,2,false),"Map"),"") -> IMP466BLK | CD9: =if(F9="REFUNDED",iferror(Vlookup(I9,'Listing SKU - Fill SKU Mapping'!A:C,3,false),"Map"),"") -> Keystone | CE9: =TEXT(G9,"YYYY") -> 2025 | CF9: =TEXT(G9,"MMMM") -> May | CG9: =IF(AND((G9-CG$1)>=0,(G9-CG$1)<=6), "This Week",IF(AND((G9-CG$1)>=-7,(G9-CG$1)<=-1), "Last Week",""))
A10: 200013169413632 | B10: 1 | C10: 109014759518921 | D10: 1 | F10: SALE | G10: 45804 | H10: 1 | I10: WM-FR-IMP-84760166-18GB6VS | J10: 465595320771 | K10: Set of 4 18 inch Gloss Black ABS Wheel Skins Compatible with 2017 - 2019 GMC Acadia SLE; 2017 - 2019 GMC Acadia SLT Impostors for 84760166 22996315 Wheel Series | L10: 2038710 | O10: LA | R10: New Orleans | S10: 70125 | T10: Marketplace standard | U10: 71.92 | V10: 61.36 | W10: 4.62 | X10: 7 | Y10: 65.98 | Z10: 0 | AA10: 0 | AB10: 0 | AC10: 0 | AD10: 0 | AE10: 0 | AF10: 0 | AG10: 0 | AH10: 0 | AI10: 0 | AJ10: 0 | AK10: 0 | AL10: 0 | AM10: 0 | AN10: 0 | AO10: 5.94 | AP10: 0 | AQ10: 0 | AR10: 0 | AS10: 0 | AT10: 0 | AU10: 0 | AV10: 0 | AW10: 0 | AX10: 0 | AY10: 0 | AZ10: 0 | BA10: 0 | BB10: 5.94 | BC10: Y | BG10: -6.6 | BH10: Wheels & Wheel Components | BI10: Tires & Wheels | BJ10: Automotive Wheel Covers & Hub Caps | BK10: PRO-119076-17.0 | BN10: N | BO10: Seller Fulfilled | BP10: Delivery | BQ10: New Seller Saving | BR10: 1.98 | BW10: =if(OR(F10="SALE",F10="REFUNDED"),IFERROR(Vlookup(I10,'Listing SKU - Fill SKU Mapping'!A:C,3,false),"Map"),"") -> Keystone | BX10: =IF(OR(F10="SALE",F10="REFUNDED")=TRUE,iferror(Vlookup(I10,'Listing SKU - Fill SKU Mapping'!A:B,2,false),"Map"),"") -> IMP466BLK | BY10: =IF(OR(F10="SALE",F10="REFUNDED")=TRUE,iferror(Vlookup(I10,'Listing SKU - Fill SKU Mapping'!A:D,4,false),"Map"),"") -> 62.33 | BZ10: =If(BW10="Keystone",11.5,"") -> 11.5 | CA10: =IF(ISNUMBER(BY10)=TRUE,BY10+BZ10,"") -> 73.83 | CB10: =if(F10="SALE",V10-CA10,"") -> -12.47 | CC10: =if(F10="REFUNDED",iferror(Vlookup(I10,'Listing SKU - Fill SKU Mapping'!A:B,2,false),"Map"),"") | CD10: =if(F10="REFUNDED",iferror(Vlookup(I10,'Listing SKU - Fill SKU Mapping'!A:C,3,false),"Map"),"") | CE10: =TEXT(G10,"YYYY") -> 2025 | CF10: =TEXT(G10,"MMMM") -> May | CG10: =IF(AND((G10-CG$1)>=0,(G10-CG$1)<=6), "This Week",IF(AND((G10-CG$1)>=-7,(G10-CG$1)<=-1), "Last Week",""))
A11: 200013143554738 | B11: 1 | C11: 109014348663493 | D11: 1 | F11: SALE | G11: 45800 | H11: 1 | I11: WM-FR-IMP-3957-17GB5DS | J11: 460776238265 | K11: Set of 4 17 inch Gloss Black Wheel Skins Covers Compatible with 13-16 Ford Fusion Impostors for 3957 Wheel Series | L11: 2038710 | O11: GA | R11: Pooler | S11: 31322 | T11: Marketplace standard | U11: 104.84 | V11: 91.12 | W11: 6.86 | X11: 7 | Y11: 97.98 | Z11: 0 | AA11: 0 | AB11: 0 | AC11: 0 | AD11: 0 | AE11: 0 | AF11: 0 | AG11: 0 | AH11: 0 | AI11: 0 | AJ11: 0 | AK11: 0 | AL11: 0 | AM11: 0 | AN11: 0 | AO11: 6.86 | AP11: 0 | AQ11: 0 | AR11: 0 | AS11: 0 | AT11: 0 | AU11: 0 | AV11: 0 | AW11: 0 | AX11: 0 | AY11: 0 | AZ11: 0 | BA11: 0 | BB11: 6.86 | BC11: Y | BG11: -9.8 | BH11: Wheels & Wheel Components | BI11: Tires & Wheels | BJ11: Automotive Wheel Covers & Hub Caps | BK11: PRO-119076-17.0 | BN11: N | BO11: Seller Fulfilled | BP11: Delivery | BQ11: New Seller Saving | BR11: 2.94 | BW11: =if(OR(F11="SALE",F11="REFUNDED"),IFERROR(Vlookup(I11,'Listing SKU - Fill SKU Mapping'!A:C,3,false),"Map"),"") -> Keystone | BX11: =IF(OR(F11="SALE",F11="REFUNDED")=TRUE,iferror(Vlookup(I11,'Listing SKU - Fill SKU Mapping'!A:B,2,false),"Map"),"") -> IMP372BLKN | BY11: =IF(OR(F11="SALE",F11="REFUNDED")=TRUE,iferror(Vlookup(I11,'Listing SKU - Fill SKU Mapping'!A:D,4,false),"Map"),"") -> 45.36 | BZ11: =If(BW11="Keystone",11.5,"") -> 11.5 | CA11: =IF(ISNUMBER(BY11)=TRUE,BY11+BZ11,"") -> 56.86 | CB11: =if(F11="SALE",V11-CA11,"") -> 34.26 | CC11: =if(F11="REFUNDED",iferror(Vlookup(I11,'Listing SKU - Fill SKU Mapping'!A:B,2,false),"Map"),"") | CD11: =if(F11="REFUNDED",iferror(Vlookup(I11,'Listing SKU - Fill SKU Mapping'!A:C,3,false),"Map"),"") | CE11: =TEXT(G11,"YYYY") -> 2025 | CF11: =TEXT(G11,"MMMM") -> May | CG11: =IF(AND((G11-CG$1)>=0,(G11-CG$1)<=6), "This Week",IF(AND((G11-CG$1)>=-7,(G11-CG$1)<=-1), "Last Week",""))
A12: 200013138589026 | B12: 1 | C12: 109014973533768 | D12: 1 | F12: SALE | G12: 45806 | H12: 1 | I12: WM-KS-FRHC-530696-16SL | J12: 467129929368 | K12: Fuel Rider Set of 4 16 inch Silver Snap-On Hubcaps With 6 Spoke Compatible With 2005-2006 Nissan Altima Standard Steel Wheel Covers | L12: 2038710 | O12: MS | R12: Brandon | S12: 39047 | T12: Marketplace standard | U12: 69.53 | V12: 60.43 | W12: 4.55 | X12: 7 | Y12: 64.98 | Z12: 0 | AA12: 0 | AB12: 0 | AC12: 0 | AD12: 0 | AE12: 0 | AF12: 0 | AG12: 0 | AH12: 0 | AI12: 0 | AJ12: 0 | AK12: 0 | AL12: 0 | AM12: 0 | AN12: 0 | AO12: 4.55 | AP12: 0 | AQ12: 0 | AR12: 0 | AS12: 0 | AT12: 0 | AU12: 0 | AV12: 0 | AW12: 0 | AX12: 0 | AY12: 0 | AZ12: 0 | BA12: 0 | BB12: 4.55 | BC12: Y | BG12: -6.5 | BH12: Wheels & Wheel Components | BI12: Tires & Wheels | BJ12: Automotive Wheel Covers & Hub Caps | BK12: PRO-119076-17.0 | BN12: N | BO12: Seller Fulfilled | BP12: Delivery | BQ12: New Seller Saving | BR12: 1.95 | BW12: =if(OR(F12="SALE",F12="REFUNDED"),IFERROR(Vlookup(I12,'Listing SKU - Fill SKU Mapping'!A:C,3,false),"Map"),"") -> Keystone | BX12: =IF(OR(F12="SALE",F12="REFUNDED")=TRUE,iferror(Vlookup(I12,'Listing SKU - Fill SKU Mapping'!A:B,2,false),"Map"),"") -> B887216S | BY12: =IF(OR(F12="SALE",F12="REFUNDED")=TRUE,iferror(Vlookup(I12,'Listing SKU - Fill SKU Mapping'!A:D,4,false),"Map"),"") -> 24.85 | BZ12: =If(BW12="Keystone",11.5,"") -> 11.5 | CA12: =IF(ISNUMBER(BY12)=TRUE,BY12+BZ12,"") -> 36.35 | CB12: =if(F12="SALE",V12-CA12,"") -> 24.08 | CC12: =if(F12="REFUNDED",iferror(Vlookup(I12,'Listing SKU - Fill SKU Mapping'!A:B,2,false),"Map"),"") | CD12: =if(F12="REFUNDED",iferror(Vlookup(I12,'Listing SKU - Fill SKU Mapping'!A:C,3,false),"Map"),"") | CE12: =TEXT(G12,"YYYY") -> 2025 | CF12: =TEXT(G12,"MMMM") -> May | CG12: =IF(AND((G12-CG$1)>=0,(G12-CG$1)<=6), "This Week",IF(AND((G12-CG$1)>=-7,(G12-CG$1)<=-1), "Last Week",""))
A13: 200013082357439 | B13: 1 | C13: 109014034395401 | D13: 1 | F13: SALE | G13: 45796 | H13: 1 | I13: WM-FR-IMP-94775676-16GB6S | J13: 460776233390 | K13: Set of 4 16 Gloss Black ABS Wheel Skins Compatible with 2015-2020 Chevrolet Colorado Base 2015-2022 Colorado WT LT Z71 2017-2022 Colorado ZR2 Impostors for 94775676 Wheel Series | L13: 2038710 | O13: OK | R13: Okmulgee | S13: 74447 | T13: Marketplace standard | U13: 121.07 | V13: 102.28 | W13: 7.7 | X13: 7 | Y13: 109.98 | Z13: 0 | AA13: 0 | AB13: 0 | AC13: 0 | AD13: 0 | AE13: 0 | AF13: 0 | AG13: 0 | AH13: 0 | AI13: 0 | AJ13: 0 | AK13: 0 | AL13: 0 | AM13: 0 | AN13: 0 | AO13: 11.09 | AP13: 0 | AQ13: 0 | AR13: 0 | AS13: 0 | AT13: 0 | AU13: 0 | AV13: 0 | AW13: 0 | AX13: 0 | AY13: 0 | AZ13: 0 | BA13: 0 | BB13: 11.09 | BC13: Y | BG13: -11 | BH13: Wheels & Wheel Components | BI13: Tires & Wheels | BJ13: Automotive Wheel Covers & Hub Caps | BK13: PRO-119076-16.0 | BN13: Y | BO13: Seller Fulfilled | BP13: Delivery | BQ13: New Seller Saving | BR13: 3.3 | BW13: =if(OR(F13="SALE",F13="REFUNDED"),IFERROR(Vlookup(I13,'Listing SKU - Fill SKU Mapping'!A:C,3,false),"Map"),"") -> Keystone | BX13: =IF(OR(F13="SALE",F13="REFUNDED")=TRUE,iferror(Vlookup(I13,'Listing SKU - Fill SKU Mapping'!A:B,2,false),"Map"),"") -> IMP444BLK | BY13: =IF(OR(F13="SALE",F13="REFUNDED")=TRUE,iferror(Vlookup(I13,'Listing SKU - Fill SKU Mapping'!A:D,4,false),"Map"),"") -> 54.05 | BZ13: =If(BW13="Keystone",11.5,"") -> 11.5 | CA13: =IF(ISNUMBER(BY13)=TRUE,BY13+BZ13,"") -> 65.55 | CB13: =if(F13="SALE",V13-CA13,"") -> 36.73 | CC13: =if(F13="REFUNDED",iferror(Vlookup(I13,'Listing SKU - Fill SKU Mapping'!A:B,2,false),"Map"),"") | CD13: =if(F13="REFUNDED",iferror(Vlookup(I13,'Listing SKU - Fill SKU Mapping'!A:C,3,false),"Map"),"") | CE13: =TEXT(G13,"YYYY") -> 2025 | CF13: =TEXT(G13,"MMMM") -> May | CG13: =IF(AND((G13-CG$1)>=0,(G13-CG$1)<=6), "This Week",IF(AND((G13-CG$1)>=-7,(G13-CG$1)<=-1), "Last Week",""))
A14: 200013082357439 | B14: 1 | C14: 109014034395401 | D14: 1 | F14: REFUNDED | G14: 45799 | H14: 1 | I14: WM-FR-IMP-94775676-16GB6S | J14: 460776233390 | K14: Set of 4 16 Gloss Black ABS Wheel Skins Compatible with 2015-2020 Chevrolet Colorado Base 2015-2022 Colorado WT LT Z71 2017-2022 Colorado ZR2 Impostors for 94775676 Wheel Series | L14: 2038710 | R14: Okmulgee | S14: 74447 | U14: -121.07 | V14: -102.28 | W14: -7.7 | X14: 0 | Y14: 0 | Z14: -109.98 | AA14: 0 | AB14: 0 | AC14: 0 | AD14: 0 | AE14: 0 | AF14: 0 | AG14: 0 | AH14: 0 | AI14: 0 | AJ14: 0 | AK14: 0 | AL14: 0 | AM14: 0 | AN14: 0 | AO14: 0 | AP14: 0 | AQ14: 0 | AR14: 0 | AS14: 0 | AT14: -11.09 | AU14: 0 | AV14: 0 | AW14: 0 | AX14: 0 | AY14: 0 | AZ14: 0 | BA14: 0 | BB14: -11.09 | BC14: Y | BD14: Return Refund | BE14: 5010 | BH14: Wheels & Wheel Components | BI14: Tires & Wheels | BL14: 1018 | BM14: Not as described/pictured | BN14: Y | BO14: Seller Fulfilled | BW14: =if(OR(F14="SALE",F14="REFUNDED"),IFERROR(Vlookup(I14,'Listing SKU - Fill SKU Mapping'!A:C,3,false),"Map"),"") -> Keystone | BX14: =IF(OR(F14="SALE",F14="REFUNDED")=TRUE,iferror(Vlookup(I14,'Listing SKU - Fill SKU Mapping'!A:B,2,false),"Map"),"") -> IMP444BLK | BY14: =IF(OR(F14="SALE",F14="REFUNDED")=TRUE,iferror(Vlookup(I14,'Listing SKU - Fill SKU Mapping'!A:D,4,false),"Map"),"") -> 54.05 | BZ14: =If(BW14="Keystone",11.5,"") -> 11.5 | CA14: =IF(ISNUMBER(BY14)=TRUE,BY14+BZ14,"") -> 65.55 | CB14: =if(F14="SALE",V14-CA14,"") | CC14: =if(F14="REFUNDED",iferror(Vlookup(I14,'Listing SKU - Fill SKU Mapping'!A:B,2,false),"Map"),"") -> IMP444BLK | CD14: =if(F14="REFUNDED",iferror(Vlookup(I14,'Listing SKU - Fill SKU Mapping'!A:C,3,false),"Map"),"") -> Keystone | CE14: =TEXT(G14,"YYYY") -> 2025 | CF14: =TEXT(G14,"MMMM") -> May | CG14: =IF(AND((G14-CG$1)>=0,(G14-CG$1)<=6), "This Week",IF(AND((G14-CG$1)>=-7,(G14-CG$1)<=-1), "Last Week",""))
A15: 200013060278696 | B15: 7 | C15: 109011942953061 | D15: 7 | F15: ADJMNT | G15: 45802 | H15: 1 | I15: WM-FR-IMP-3943-17GB5SP | J15: 460776234854 | K15: Set of 4 17 inch Gloss Black Wheel Skins Covers Compatible with 17-19 Ford Escape SE 13-16 Ford Escape Impostors for 3943 Wheel Series | L15: 2038710 | O15: CA | R15: Whittier | S15: 90605 | T15: Marketplace standard | U15: 0 | V15: -8.89 | W15: 0 | X15: 0 | Y15: 0 | Z15: 0 | AA15: 0 | AB15: 0 | AC15: 0 | AD15: 0 | AE15: 0 | AF15: 0 | AG15: 0 | AH15: 0 | AI15: 0 | AJ15: 0 | AK15: 0 | AL15: 0 | AM15: 0 | AN15: 0 | AO15: 0 | AP15: 0 | AQ15: 0 | AR15: 0 | AS15: 0 | AT15: 0 | AU15: 0 | AV15: 0 | AW15: 0 | AX15: 0 | AY15: 0 | AZ15: 0 | BA15: 0 | BB15: 0 | BC15: Y | BD15: Walmart Return Shipping Charge | BE15: 5013 | BH15: Wheels & Wheel Components | BI15: Tires & Wheels | BN15: N | BO15: Seller Fulfilled | BW15: =if(OR(F15="SALE",F15="REFUNDED"),IFERROR(Vlookup(I15,'Listing SKU - Fill SKU Mapping'!A:C,3,false),"Map"),"") | BX15: =IF(OR(F15="SALE",F15="REFUNDED")=TRUE,iferror(Vlookup(I15,'Listing SKU - Fill SKU Mapping'!A:B,2,false),"Map"),"") | BY15: =IF(OR(F15="SALE",F15="REFUNDED")=TRUE,iferror(Vlookup(I15,'Listing SKU - Fill SKU Mapping'!A:D,4,false),"Map"),"") | BZ15: =If(BW15="Keystone",11.5,"") | CA15: =IF(ISNUMBER(BY15)=TRUE,BY15+BZ15,"") | CB15: =if(F15="SALE",V15-CA15,"") | CC15: =if(F15="REFUNDED",iferror(Vlookup(I15,'Listing SKU - Fill SKU Mapping'!A:B,2,false),"Map"),"") | CD15: =if(F15="REFUNDED",iferror(Vlookup(I15,'Listing SKU - Fill SKU Mapping'!A:C,3,false),"Map"),"") | CE15: =TEXT(G15,"YYYY") -> 2025 | CF15: =TEXT(G15,"MMMM") -> May | CG15: =IF(AND((G15-CG$1)>=0,(G15-CG$1)<=6), "This Week",IF(AND((G15-CG$1)>=-7,(G15-CG$1)<=-1), "Last Week",""))
A16: 200013049604965 | B16: 1 | C16: 109011426675392 | D16: 1 | F16: ADJMNT | G16: 45795 | H16: 1 | I16: WM-FR-IMP-5833-17GB5DS | J16: 460776235042 | K16: 17 inch Gloss Black ABS Wheel Skins Set Compatible with 2018-2021 GMC Terrain SL 2018-2023 GMC Terrain SLE & Impostors for 5833 Wheel Series | L16: 2038710 | O16: VA | R16: South Prince George | S16: 23805 | T16: Marketplace standard | U16: 0 | V16: -8.89 | W16: 0 | X16: 0 | Y16: 0 | Z16: 0 | AA16: 0 | AB16: 0 | AC16: 0 | AD16: 0 | AE16: 0 | AF16: 0 | AG16: 0 | AH16: 0 | AI16: 0 | AJ16: 0 | AK16: 0 | AL16: 0 | AM16: 0 | AN16: 0 | AO16: 0 | AP16: 0 | AQ16: 0 | AR16: 0 | AS16: 0 | AT16: 0 | AU16: 0 | AV16: 0 | AW16: 0 | AX16: 0 | AY16: 0 | AZ16: 0 | BA16: 0 | BB16: 0 | BC16: Y | BD16: Walmart Return Shipping Charge | BE16: 5013 | BH16: Wheels & Wheel Components | BI16: Tires & Wheels | BN16: N | BO16: Seller Fulfilled | BW16: =if(OR(F16="SALE",F16="REFUNDED"),IFERROR(Vlookup(I16,'Listing SKU - Fill SKU Mapping'!A:C,3,false),"Map"),"") | BX16: =IF(OR(F16="SALE",F16="REFUNDED")=TRUE,iferror(Vlookup(I16,'Listing SKU - Fill SKU Mapping'!A:B,2,false),"Map"),"") | BY16: =IF(OR(F16="SALE",F16="REFUNDED")=TRUE,iferror(Vlookup(I16,'Listing SKU - Fill SKU Mapping'!A:D,4,false),"Map"),"") | BZ16: =If(BW16="Keystone",11.5,"") | CA16: =IF(ISNUMBER(BY16)=TRUE,BY16+BZ16,"") | CB16: =if(F16="SALE",V16-CA16,"") | CC16: =if(F16="REFUNDED",iferror(Vlookup(I16,'Listing SKU - Fill SKU Mapping'!A:B,2,false),"Map"),"") | CD16: =if(F16="REFUNDED",iferror(Vlookup(I16,'Listing SKU - Fill SKU Mapping'!A:C,3,false),"Map"),"") | CE16: =TEXT(G16,"YYYY") -> 2025 | CF16: =TEXT(G16,"MMMM") -> May | CG16: =IF(AND((G16-CG$1)>=0,(G16-CG$1)<=6), "This Week",IF(AND((G16-CG$1)>=-7,(G16-CG$1)<=-1), "Last Week",""))
A17: 200013038493104 | B17: 1 | C17: 109011116508241 | D17: 1 | F17: ADJMNT | G17: 45802 | H17: 1 | I17: WM-FR-IMP-2363-20CH5SP | J17: 464567112352 | K17: Set of 4 20 inch Chrome Wheel Skins Covers compatible with 09-10 Dodge Ram 1500 11-24 Ram 1500 Classic Sport Laramie Rebel Tradesman Big Horn SLT Express Lone Star Limited Impostors | L17: 2038710 | O17: IN | R17: Beech Grove | S17: 46107 | T17: Marketplace standard | U17: 0 | V17: -10.81 | W17: 0 | X17: 0 | Y17: 0 | Z17: 0 | AA17: 0 | AB17: 0 | AC17: 0 | AD17: 0 | AE17: 0 | AF17: 0 | AG17: 0 | AH17: 0 | AI17: 0 | AJ17: 0 | AK17: 0 | AL17: 0 | AM17: 0 | AN17: 0 | AO17: 0 | AP17: 0 | AQ17: 0 | AR17: 0 | AS17: 0 | AT17: 0 | AU17: 0 | AV17: 0 | AW17: 0 | AX17: 0 | AY17: 0 | AZ17: 0 | BA17: 0 | BB17: 0 | BC17: Y | BD17: Walmart Return Shipping Charge | BE17: 5013 | BH17: Wheels & Wheel Components | BI17: Tires & Wheels | BN17: N | BO17: Seller Fulfilled | BW17: =if(OR(F17="SALE",F17="REFUNDED"),IFERROR(Vlookup(I17,'Listing SKU - Fill SKU Mapping'!A:C,3,false),"Map"),"") | BX17: =IF(OR(F17="SALE",F17="REFUNDED")=TRUE,iferror(Vlookup(I17,'Listing SKU - Fill SKU Mapping'!A:B,2,false),"Map"),"") | BY17: =IF(OR(F17="SALE",F17="REFUNDED")=TRUE,iferror(Vlookup(I17,'Listing SKU - Fill SKU Mapping'!A:D,4,false),"Map"),"") | BZ17: =If(BW17="Keystone",11.5,"") | CA17: =IF(ISNUMBER(BY17)=TRUE,BY17+BZ17,"") | CB17: =if(F17="SALE",V17-CA17,"") | CC17: =if(F17="REFUNDED",iferror(Vlookup(I17,'Listing SKU - Fill SKU Mapping'!A:B,2,false),"Map"),"") | CD17: =if(F17="REFUNDED",iferror(Vlookup(I17,'Listing SKU - Fill SKU Mapping'!A:C,3,false),"Map"),"") | CE17: =TEXT(G17,"YYYY") -> 2025 | CF17: =TEXT(G17,"MMMM") -> May | CG17: =IF(AND((G17-CG$1)>=0,(G17-CG$1)<=6), "This Week",IF(AND((G17-CG$1)>=-7,(G17-CG$1)<=-1), "Last Week",""))
A18: 200012993559082 | B18: 1 | C18: 109011114761058 | D18: 1 | F18: ADJMNT | G18: 45795 | H18: 1 | I18: WM-FR-IMP-10043-18CH5DS | J18: 464567131070 | K18: Set of 4 18 inch Chrome Wheel Skins Covers Compatible with 15-18 Ford Edge Impostors for 10043 Wheel Series | L18: 2038710 | O18: TX | R18: Houston | S18: 77040 | T18: Marketplace standard | U18: 0 | V18: -10.81 | W18: 0 | X18: 0 | Y18: 0 | Z18: 0 | AA18: 0 | AB18: 0 | AC18: 0 | AD18: 0 | AE18: 0 | AF18: 0 | AG18: 0 | AH18: 0 | AI18: 0 | AJ18: 0 | AK18: 0 | AL18: 0 | AM18: 0 | AN18: 0 | AO18: 0 | AP18: 0 | AQ18: 0 | AR18: 0 | AS18: 0 | AT18: 0 | AU18: 0 | AV18: 0 | AW18: 0 | AX18: 0 | AY18: 0 | AZ18: 0 | BA18: 0 | BB18: 0 | BC18: Y | BD18: Walmart Return Shipping Charge | BE18: 5013 | BH18: Wheels & Wheel Components | BI18: Tires & Wheels | BN18: N | BO18: Seller Fulfilled | BW18: =if(OR(F18="SALE",F18="REFUNDED"),IFERROR(Vlookup(I18,'Listing SKU - Fill SKU Mapping'!A:C,3,false),"Map"),"") | BX18: =IF(OR(F18="SALE",F18="REFUNDED")=TRUE,iferror(Vlookup(I18,'Listing SKU - Fill SKU Mapping'!A:B,2,false),"Map"),"") | BY18: =IF(OR(F18="SALE",F18="REFUNDED")=TRUE,iferror(Vlookup(I18,'Listing SKU - Fill SKU Mapping'!A:D,4,false),"Map"),"") | BZ18: =If(BW18="Keystone",11.5,"") | CA18: =IF(ISNUMBER(BY18)=TRUE,BY18+BZ18,"") | CB18: =if(F18="SALE",V18-CA18,"") | CC18: =if(F18="REFUNDED",iferror(Vlookup(I18,'Listing SKU - Fill SKU Mapping'!A:B,2,false),"Map"),"") | CD18: =if(F18="REFUNDED",iferror(Vlookup(I18,'Listing SKU - Fill SKU Mapping'!A:C,3,false),"Map"),"") | CE18: =TEXT(G18,"YYYY") -> 2025 | CF18: =TEXT(G18,"MMMM") -> May | CG18: =IF(AND((G18-CG$1)>=0,(G18-CG$1)<=6), "This Week",IF(AND((G18-CG$1)>=-7,(G18-CG$1)<=-1), "Last Week",""))
A19: 200012934607014 | B19: 1 | C19: 109010168324919 | D19: 1 | F19: ADJMNT | G19: 45795 | H19: 1 | I19: WM-FR-IMP-DS7Z1007Q-17CC10S | J19: 460776230283 | K19: Set of 4 17 Chrome & Charcoal ABS Wheel Skins Compatible with 2017-2020 Ford Fusion SE 2015-2016 Ford Fusion Impostors for DS7Z1007Q Wheel Series | L19: 2038710 | O19: VA | R19: Roanoke | S19: 24013 | T19: Marketplace standard | U19: 0 | V19: -8.89 | W19: 0 | X19: 0 | Y19: 0 | Z19: 0 | AA19: 0 | AB19: 0 | AC19: 0 | AD19: 0 | AE19: 0 | AF19: 0 | AG19: 0 | AH19: 0 | AI19: 0 | AJ19: 0 | AK19: 0 | AL19: 0 | AM19: 0 | AN19: 0 | AO19: 0 | AP19: 0 | AQ19: 0 | AR19: 0 | AS19: 0 | AT19: 0 | AU19: 0 | AV19: 0 | AW19: 0 | AX19: 0 | AY19: 0 | AZ19: 0 | BA19: 0 | BB19: 0 | BC19: Y | BD19: Walmart Return Shipping Charge | BE19: 5013 | BH19: Wheels & Wheel Components | BI19: Tires & Wheels | BN19: N | BO19: Seller Fulfilled | BW19: =if(OR(F19="SALE",F19="REFUNDED"),IFERROR(Vlookup(I19,'Listing SKU - Fill SKU Mapping'!A:C,3,false),"Map"),"") | BX19: =IF(OR(F19="SALE",F19="REFUNDED")=TRUE,iferror(Vlookup(I19,'Listing SKU - Fill SKU Mapping'!A:B,2,false),"Map"),"") | BY19: =IF(OR(F19="SALE",F19="REFUNDED")=TRUE,iferror(Vlookup(I19,'Listing SKU - Fill SKU Mapping'!A:D,4,false),"Map"),"") | BZ19: =If(BW19="Keystone",11.5,"") | CA19: =IF(ISNUMBER(BY19)=TRUE,BY19+BZ19,"") | CB19: =if(F19="SALE",V19-CA19,"") | CC19: =if(F19="REFUNDED",iferror(Vlookup(I19,'Listing SKU - Fill SKU Mapping'!A:B,2,false),"Map"),"") | CD19: =if(F19="REFUNDED",iferror(Vlookup(I19,'Listing SKU - Fill SKU Mapping'!A:C,3,false),"Map"),"") | CE19: =TEXT(G19,"YYYY") -> 2025 | CF19: =TEXT(G19,"MMMM") -> May | CG19: =IF(AND((G19-CG$1)>=0,(G19-CG$1)<=6), "This Week",IF(AND((G19-CG$1)>=-7,(G19-CG$1)<=-1), "Last Week",""))
A20: 200013328886328 | B20: 1 | C20: 109012673709835 | D20: 1 | F20: SALE | G20: 45783 | H20: 1 | I20: WM-FR-IMP-5473-16GB5SP | J20: 460776230986 | K20: Set of 4 16 inch Gloss Black ABS Wheel Skins Compatible with 11-15 Chevrolet Cruze 16 Cruze Limited Impostors for 5473 5674 Wheel Series | L20: 2038710 | O20: TX | R20: Mcallen | S20: 78501 | T20: Marketplace standard | U20: 98.49 | V20: 84.61 | W20: 6.37 | X20: 7 | Y20: 90.98 | Z20: 0 | AA20: 0 | AB20: 0 | AC20: 0 | AD20: 0 | AE20: 0 | AF20: 0 | AG20: 0 | AH20: 0 | AI20: 0 | AJ20: 0 | AK20: 0 | AL20: 0 | AM20: 0 | AN20: 0 | AO20: 7.51 | AP20: 0 | AQ20: 0 | AR20: 0 | AS20: 0 | AT20: 0 | AU20: 0 | AV20: 0 | AW20: 0 | AX20: 0 | AY20: 0 | AZ20: 0 | BA20: 0 | BB20: 7.51 | BC20: Y | BG20: -9.1 | BH20: Wheels & Wheel Components | BI20: Tires & Wheels | BJ20: Automotive Wheel Covers & Hub Caps | BK20: PRO-119076-14.0 | BN20: N | BO20: Seller Fulfilled | BP20: Delivery | BQ20: New Seller Saving | BR20: 2.73 | BW20: =if(OR(F20="SALE",F20="REFUNDED"),IFERROR(Vlookup(I20,'Listing SKU - Fill SKU Mapping'!A:C,3,false),"Map"),"") -> Keystone | BX20: =IF(OR(F20="SALE",F20="REFUNDED")=TRUE,iferror(Vlookup(I20,'Listing SKU - Fill SKU Mapping'!A:B,2,false),"Map"),"") -> IMP375BLK | BY20: =IF(OR(F20="SALE",F20="REFUNDED")=TRUE,iferror(Vlookup(I20,'Listing SKU - Fill SKU Mapping'!A:D,4,false),"Map"),"") -> 41.03 | BZ20: =If(BW20="Keystone",11.5,"") -> 11.5 | CA20: =IF(ISNUMBER(BY20)=TRUE,BY20+BZ20,"") -> 52.53 | CB20: =if(F20="SALE",V20-CA20,"") -> 32.08 | CC20: =if(F20="REFUNDED",iferror(Vlookup(I20,'Listing SKU - Fill SKU Mapping'!A:B,2,false),"Map"),"") | CD20: =if(F20="REFUNDED",iferror(Vlookup(I20,'Listing SKU - Fill SKU Mapping'!A:C,3,false),"Map"),"") | CE20: =TEXT(G20,"YYYY") -> 2025 | CF20: =TEXT(G20,"MMMM") -> May | CG20: =IF(AND((G20-CG$1)>=0,(G20-CG$1)<=6), "This Week",IF(AND((G20-CG$1)>=-7,(G20-CG$1)<=-1), "Last Week",""))
A21: 200013309638819 | B21: 1 | C21: 109013192839887 | D21: 1 | F21: SALE | G21: 45789 | H21: 1 | I21: WM-FR-IMP-5646-18CH5DS | J21: 460776229027 | K21: 18 inch Chrome ABS Wheel Skins Set Compatible with 2014-2018 Chevrolet Silverado 1500 LT LTZ 2015-2020 Tahoe Suburban LS LT & Impostors for 5646 Wheel Series | L21: 2038710 | O21: IN | R21: Evansville | S21: 47714 | T21: Marketplace standard | U21: 139.08 | V21: 120.88 | W21: 9.1 | X21: 7 | Y21: 129.98 | Z21: 0 | AA21: 0 | AB21: 0 | AC21: 0 | AD21: 0 | AE21: 0 | AF21: 0 | AG21: 0 | AH21: 0 | AI21: 0 | AJ21: 0 | AK21: 0 | AL21: 0 | AM21: 0 | AN21: 0 | AO21: 9.1 | AP21: 0 | AQ21: 0 | AR21: 0 | AS21: 0 | AT21: 0 | AU21: 0 | AV21: 0 | AW21: 0 | AX21: 0 | AY21: 0 | AZ21: 0 | BA21: 0 | BB21: 9.1 | BC21: Y | BG21: -13 | BH21: Wheels & Wheel Components | BI21: Tires & Wheels | BJ21: Automotive Wheel Covers & Hub Caps | BK21: PRO-119076-15.0 | BN21: N | BO21: Seller Fulfilled | BP21: Delivery | BQ21: New Seller Saving | BR21: 3.9 | BW21: =if(OR(F21="SALE",F21="REFUNDED"),IFERROR(Vlookup(I21,'Listing SKU - Fill SKU Mapping'!A:C,3,false),"Map"),"") -> Keystone | BX21: =IF(OR(F21="SALE",F21="REFUNDED")=TRUE,iferror(Vlookup(I21,'Listing SKU - Fill SKU Mapping'!A:B,2,false),"Map"),"") -> IMP377XN | BY21: =IF(OR(F21="SALE",F21="REFUNDED")=TRUE,iferror(Vlookup(I21,'Listing SKU - Fill SKU Mapping'!A:D,4,false),"Map"),"") -> 67.85 | BZ21: =If(BW21="Keystone",11.5,"") -> 11.5 | CA21: =IF(ISNUMBER(BY21)=TRUE,BY21+BZ21,"") -> 79.35 | CB21: =if(F21="SALE",V21-CA21,"") -> 41.53 | CC21: =if(F21="REFUNDED",iferror(Vlookup(I21,'Listing SKU - Fill SKU Mapping'!A:B,2,false),"Map"),"") | CD21: =if(F21="REFUNDED",iferror(Vlookup(I21,'Listing SKU - Fill SKU Mapping'!A:C,3,false),"Map"),"") | CE21: =TEXT(G21,"YYYY") -> 2025 | CF21: =TEXT(G21,"MMMM") -> May | CG21: =IF(AND((G21-CG$1)>=0,(G21-CG$1)<=6), "This Week",IF(AND((G21-CG$1)>=-7,(G21-CG$1)<=-1), "Last Week",""))
A22: 200013296634411 | B22: 1 | C22: 109013191993463 | D22: 1 | F22: SALE | G22: 45789 | H22: 1 | I22: WM-FR-IMP-4261148040-16CH5DMS | J22: 464567125864 | K22: Set of 4 16 inch Chrome Wheel Skins Covers compatible with 01-05 Toyota RAV4 01-07 Toyota Highlander Impostors for 4261148040 Wheel Series | L22: 2038710 | O22: FL | R22: Palm Bay | S22: 32908 | T22: Marketplace standard | U22: 98.42 | V22: 85.54 | W22: 6.44 | X22: 7 | Y22: 91.98 | Z22: 0 | AA22: 0 | AB22: 0 | AC22: 0 | AD22: 0 | AE22: 0 | AF22: 0 | AG22: 0 | AH22: 0 | AI22: 0 | AJ22: 0 | AK22: 0 | AL22: 0 | AM22: 0 | AN22: 0 | AO22: 6.44 | AP22: 0 | AQ22: 0 | AR22: 0 | AS22: 0 | AT22: 0 | AU22: 0 | AV22: 0 | AW22: 0 | AX22: 0 | AY22: 0 | AZ22: 0 | BA22: 0 | BB22: 6.44 | BC22: Y | BG22: -9.2 | BH22: Wheels & Wheel Components | BI22: Tires & Wheels | BJ22: Automotive Wheel Covers & Hub Caps | BK22: PRO-119076-15.0 | BN22: N | BO22: Seller Fulfilled | BP22: Delivery | BQ22: New Seller Saving | BR22: 2.76 | BW22: =if(OR(F22="SALE",F22="REFUNDED"),IFERROR(Vlookup(I22,'Listing SKU - Fill SKU Mapping'!A:C,3,false),"Map"),"") -> Keystone | BX22: =IF(OR(F22="SALE",F22="REFUNDED")=TRUE,iferror(Vlookup(I22,'Listing SKU - Fill SKU Mapping'!A:B,2,false),"Map"),"") -> IMP42X | BY22: =IF(OR(F22="SALE",F22="REFUNDED")=TRUE,iferror(Vlookup(I22,'Listing SKU - Fill SKU Mapping'!A:D,4,false),"Map"),"") -> 51.28 | BZ22: =If(BW22="Keystone",11.5,"") -> 11.5 | CA22: =IF(ISNUMBER(BY22)=TRUE,BY22+BZ22,"") -> 62.78 | CB22: =if(F22="SALE",V22-CA22,"") -> 22.76 | CC22: =if(F22="REFUNDED",iferror(Vlookup(I22,'Listing SKU - Fill SKU Mapping'!A:B,2,false),"Map"),"") | CD22: =if(F22="REFUNDED",iferror(Vlookup(I22,'Listing SKU - Fill SKU Mapping'!A:C,3,false),"Map"),"") | CE22: =TEXT(G22,"YYYY") -> 2025 | CF22: =TEXT(G22,"MMMM") -> May | CG22: =IF(AND((G22-CG$1)>=0,(G22-CG$1)<=6), "This Week",IF(AND((G22-CG$1)>=-7,(G22-CG$1)<=-1), "Last Week",""))
A23: 200013250701552 | B23: 1 | C23: 109013412941626 | D23: 1 | F23: SALE | G23: 45790 | H23: 1 | I23: WM-FR-IMP-63927-17CH5SP | J23: 460776231020 | K23: Set of 4 17 inch Chrome Wheel Skins Covers compatible with 07-11 Honda CR-V LX Impostors for 63927 Wheel Series | L23: 2038710 | O23: WI | R23: New Berlin | S23: 53151 | T23: Marketplace standard | U23: 123.88 | V23: 109.72 | W23: 8.26 | X23: 7 | Y23: 117.98 | Z23: 0 | AA23: 0 | AB23: 0 | AC23: 0 | AD23: 0 | AE23: 0 | AF23: 0 | AG23: 0 | AH23: 0 | AI23: 0 | AJ23: 0 | AK23: 0 | AL23: 0 | AM23: 0 | AN23: 0 | AO23: 5.9 | AP23: 0 | AQ23: 0 | AR23: 0 | AS23: 0 | AT23: 0 | AU23: 0 | AV23: 0 | AW23: 0 | AX23: 0 | AY23: 0 | AZ23: 0 | BA23: 0 | BB23: 5.9 | BC23: Y | BG23: -11.8 | BH23: Wheels & Wheel Components | BI23: Tires & Wheels | BJ23: Automotive Wheel Covers & Hub Caps | BK23: PRO-119076-15.0 | BN23: N | BO23: Seller Fulfilled | BP23: Delivery | BQ23: New Seller Saving | BR23: 3.54 | BW23: =if(OR(F23="SALE",F23="REFUNDED"),IFERROR(Vlookup(I23,'Listing SKU - Fill SKU Mapping'!A:C,3,false),"Map"),"") -> Keystone | BX23: =IF(OR(F23="SALE",F23="REFUNDED")=TRUE,iferror(Vlookup(I23,'Listing SKU - Fill SKU Mapping'!A:B,2,false),"Map"),"") -> IMP75X | BY23: =IF(OR(F23="SALE",F23="REFUNDED")=TRUE,iferror(Vlookup(I23,'Listing SKU - Fill SKU Mapping'!A:D,4,false),"Map"),"") -> 59.57 | BZ23: =If(BW23="Keystone",11.5,"") -> 11.5 | CA23: =IF(ISNUMBER(BY23)=TRUE,BY23+BZ23,"") -> 71.07 | CB23: =if(F23="SALE",V23-CA23,"") -> 38.65 | CC23: =if(F23="REFUNDED",iferror(Vlookup(I23,'Listing SKU - Fill SKU Mapping'!A:B,2,false),"Map"),"") | CD23: =if(F23="REFUNDED",iferror(Vlookup(I23,'Listing SKU - Fill SKU Mapping'!A:C,3,false),"Map"),"") | CE23: =TEXT(G23,"YYYY") -> 2025 | CF23: =TEXT(G23,"MMMM") -> May | CG23: =IF(AND((G23-CG$1)>=0,(G23-CG$1)<=6), "This Week",IF(AND((G23-CG$1)>=-7,(G23-CG$1)<=-1), "Last Week",""))
A24: 200013222975528 | B24: 1 | C24: 109013397530691 | D24: 1 | F24: SALE | G24: 45789 | H24: 1 | I24: WM-FR-IMP-LJ6Z1007A-17GB10S | J24: 460776231785 | K24: 17 inch Gloss Black ABS Wheel Skins Set Compatible with 2020-2022 Ford Escape & Impostors for LJ6Z1007A Wheel Series | L24: 2038710 | O24: MD | R24: Frederick | S24: 21703 | T24: Marketplace standard | U24: 108.1 | V24: 94.84 | W24: 7.14 | X24: 7 | Y24: 101.98 | Z24: 0 | AA24: 0 | AB24: 0 | AC24: 0 | AD24: 0 | AE24: 0 | AF24: 0 | AG24: 0 | AH24: 0 | AI24: 0 | AJ24: 0 | AK24: 0 | AL24: 0 | AM24: 0 | AN24: 0 | AO24: 6.12 | AP24: 0 | AQ24: 0 | AR24: 0 | AS24: 0 | AT24: 0 | AU24: 0 | AV24: 0 | AW24: 0 | AX24: 0 | AY24: 0 | AZ24: 0 | BA24: 0 | BB24: 6.12 | BC24: Y | BG24: -10.2 | BH24: Wheels & Wheel Components | BI24: Tires & Wheels | BJ24: Automotive Wheel Covers & Hub Caps | BK24: PRO-119076-15.0 | BN24: N | BO24: Seller Fulfilled | BP24: Delivery | BQ24: New Seller Saving | BR24: 3.06 | BW24: =if(OR(F24="SALE",F24="REFUNDED"),IFERROR(Vlookup(I24,'Listing SKU - Fill SKU Mapping'!A:C,3,false),"Map"),"") -> Keystone | BX24: =IF(OR(F24="SALE",F24="REFUNDED")=TRUE,iferror(Vlookup(I24,'Listing SKU - Fill SKU Mapping'!A:B,2,false),"Map"),"") -> IMP462BLK | BY24: =IF(OR(F24="SALE",F24="REFUNDED")=TRUE,iferror(Vlookup(I24,'Listing SKU - Fill SKU Mapping'!A:D,4,false),"Map"),"") -> 48.52 | BZ24: =If(BW24="Keystone",11.5,"") -> 11.5 | CA24: =IF(ISNUMBER(BY24)=TRUE,BY24+BZ24,"") -> 60.02 | CB24: =if(F24="SALE",V24-CA24,"") -> 34.82 | CC24: =if(F24="REFUNDED",iferror(Vlookup(I24,'Listing SKU - Fill SKU Mapping'!A:B,2,false),"Map"),"") | CD24: =if(F24="REFUNDED",iferror(Vlookup(I24,'Listing SKU - Fill SKU Mapping'!A:C,3,false),"Map"),"") | CE24: =TEXT(G24,"YYYY") -> 2025 | CF24: =TEXT(G24,"MMMM") -> May | CG24: =IF(AND((G24-CG$1)>=0,(G24-CG$1)<=6), "This Week",IF(AND((G24-CG$1)>=-7,(G24-CG$1)<=-1), "Last Week",""))
